Workbook

Sheet Painel
A1: PAINEL EXECUTIVO — Orçamento 2026 TI
A2: Acompanha o mês selecionado na aba Comparativo (célula B3). Desvio positivo = gastou acima do orçado. ATENÇÃO: confira a coluna 'Linhas lançadas' — desvio negativo em linha não lançada é ausência de dado, não economia.
A3: Mês de referência: | B3: =Comparativo!$B$3 | C3: (altere na aba Comparativo)
A5: Departamento | B5: Bloco | C5: Orçado do ano | D5: Planejado acum. | E5: Realizado acum. | F5: Desvio (R$) | G5: Desvio (%) | H5: % Executado do ano | I5: Linhas lançadas
A6: TI | B6: Equipe | C6: =SUMIFS(Planejado!$T$5:$T$22,Planejado!$B$5:$B$22,"TI",Planejado!$C$5:$C$22,"Equipe") | D6: =SUMIFS(Comparativo!$I$6:$I$23,Comparativo!$B$6:$B$23,"TI",Comparativo!$C$6:$C$23,"Equipe") | E6: =SUMIFS(Comparativo!$J$6:$J$23,Comparativo!$B$6:$B$23,"TI",Comparativo!$C$6:$C$23,"Equipe") | F6: =E6-D6 | G6: =IFERROR(F6/D6,"") | H6: =IFERROR(E6/C6,"") | I6: =COUNTIFS(Comparativo!$P$6:$P$23,">0",Comparativo!$B$6:$B$23,"TI",Comparativo!$C$6:$C$23,"Equipe")&" de "&COUNTIFS(Comparativo!$A$6:$A$23,"?*",Comparativo!$B$6:$B$23,"TI",Comparativo!$C$6:$C$23,"Equipe")
A7: TI | B7: Despesas | C7: =SUMIFS(Planejado!$T$5:$T$22,Planejado!$B$5:$B$22,"TI",Planejado!$C$5:$C$22,"Despesas") | D7: =SUMIFS(Comparativo!$I$6:$I$23,Comparativo!$B$6:$B$23,"TI",Comparativo!$C$6:$C$23,"Despesas") | E7: =SUMIFS(Comparativo!$J$6:$J$23,Comparativo!$B$6:$B$23,"TI",Comparativo!$C$6:$C$23,"Despesas") | F7: =E7-D7 | G7: =IFERROR(F7/D7,"") | H7: =IFERROR(E7/C7,"") | I7: =COUNTIFS(Comparativo!$P$6:$P$23,">0",Comparativo!$B$6:$B$23,"TI",Comparativo!$C$6:$C$23,"Despesas")&" de "&COUNTIFS(Comparativo!$A$6:$A$23,"?*",Comparativo!$B$6:$B$23,"TI",Comparativo!$C$6:$C$23,"Despesas")
A8: TI | B8: Equipe + Despesas | C8: =SUMIFS(Planejado!$T$5:$T$22,Planejado!$B$5:$B$22,"TI") | D8: =SUMIFS(Comparativo!$I$6:$I$23,Comparativo!$B$6:$B$23,"TI") | E8: =SUMIFS(Comparativo!$J$6:$J$23,Comparativo!$B$6:$B$23,"TI") | F8: =E8-D8 | G8: =IFERROR(F8/D8,"") | H8: =IFERROR(E8/C8,"") | I8: =COUNTIFS(Comparativo!$P$6:$P$23,">0",Comparativo!$B$6:$B$23,"TI")&" de "&COUNTIFS(Comparativo!$A$6:$A$23,"?*",Comparativo!$B$6:$B$23,"TI")
A11: ECONOMIA GERADA — acumulado de janeiro até o mês de referência
A12: Economia bruta | C12: =-SUMIF(Comparativo!$Q$6:$Q$23,"<0") | D12: Soma de tudo que ficou abaixo do orçado
A13: (−) Gastos acima do orçado | C13: =-SUMIF(Comparativo!$Q$6:$Q$23,">0") | D13: Estouros que consomem parte da economia
A14: =ECONOMIA LÍQUIDA | C14: =-SUM(Comparativo!$Q$6:$Q$23) | D14: O número defensável: só linhas comparáveis
A15: Projeção para o ano | C15: =IFERROR(-SUM(Comparativo!$Q$6:$Q$23)/Comparativo!$D$3*12,"") | D15: Extrapolação linear, se o padrão dos meses fechados se mantiver
A16: % sobre o orçado do período | C16: =IFERROR(-SUM(Comparativo!$Q$6:$Q$23)/SUM(Comparativo!$S$6:$S$23),"") | D16: Economia líquida ÷ planejado das linhas que entram na conta
A17: Fora desta conta: linhas sem nenhum lançamento. Só entra o que foi efetivamente lançado e é comparável.
A19: DE ONDE VEIO A ECONOMIA (top 5)
A20: # | B20: Item | C20: Departamento | D20: Planejado acum. | E20: Realizado acum. | F20: Economia (R$) | G20: % da linha
A21: 1 | B21: =IFERROR(INDEX(Comparativo!$D$6:$D$23,MATCH(LARGE(Comparativo!$R$6:$R$23,A21),Comparativo!$R$6:$R$23,0)),"") | C21: =IFERROR(INDEX(Comparativo!$B$6:$B$23,MATCH(LARGE(Comparativo!$R$6:$R$23,A21),Comparativo!$R$6:$R$23,0)),"") | D21: =IFERROR(INDEX(Comparativo!$I$6:$I$23,MATCH(LARGE(Comparativo!$R$6:$R$23,A21),Comparativo!$R$6:$R$23,0)),"") | E21: =IFERROR(INDEX(Comparativo!$J$6:$J$23,MATCH(LARGE(Comparativo!$R$6:$R$23,A21),Comparativo!$R$6:$R$23,0)),"") | F21: =IFERROR(-IFERROR(INDEX(Comparativo!$K$6:$K$23,MATCH(LARGE(Comparativo!$R$6:$R$23,A21),Comparativo!$R$6:$R$23,0)),""),"") | G21: =IFERROR(F21/D21,"")
A22: 2 | B22: =IFERROR(INDEX(Comparativo!$D$6:$D$23,MATCH(LARGE(Comparativo!$R$6:$R$23,A22),Comparativo!$R$6:$R$23,0)),"") | C22: =IFERROR(INDEX(Comparativo!$B$6:$B$23,MATCH(LARGE(Comparativo!$R$6:$R$23,A22),Comparativo!$R$6:$R$23,0)),"") | D22: =IFERROR(INDEX(Comparativo!$I$6:$I$23,MATCH(LARGE(Comparativo!$R$6:$R$23,A22),Comparativo!$R$6:$R$23,0)),"") | E22: =IFERROR(INDEX(Comparativo!$J$6:$J$23,MATCH(LARGE(Comparativo!$R$6:$R$23,A22),Comparativo!$R$6:$R$23,0)),"") | F22: =IFERROR(-IFERROR(INDEX(Comparativo!$K$6:$K$23,MATCH(LARGE(Comparativo!$R$6:$R$23,A22),Comparativo!$R$6:$R$23,0)),""),"") | G22: =IFERROR(F22/D22,"")
A23: 3 | B23: =IFERROR(INDEX(Comparativo!$D$6:$D$23,MATCH(LARGE(Comparativo!$R$6:$R$23,A23),Comparativo!$R$6:$R$23,0)),"") | C23: =IFERROR(INDEX(Comparativo!$B$6:$B$23,MATCH(LARGE(Comparativo!$R$6:$R$23,A23),Comparativo!$R$6:$R$23,0)),"") | D23: =IFERROR(INDEX(Comparativo!$I$6:$I$23,MATCH(LARGE(Comparativo!$R$6:$R$23,A23),Comparativo!$R$6:$R$23,0)),"") | E23: =IFERROR(INDEX(Comparativo!$J$6:$J$23,MATCH(LARGE(Comparativo!$R$6:$R$23,A23),Comparativo!$R$6:$R$23,0)),"") | F23: =IFERROR(-IFERROR(INDEX(Comparativo!$K$6:$K$23,MATCH(LARGE(Comparativo!$R$6:$R$23,A23),Comparativo!$R$6:$R$23,0)),""),"") | G23: =IFERROR(F23/D23,"")
A24: 4 | B24: =IFERROR(INDEX(Comparativo!$D$6:$D$23,MATCH(LARGE(Comparativo!$R$6:$R$23,A24),Comparativo!$R$6:$R$23,0)),"") | C24: =IFERROR(INDEX(Comparativo!$B$6:$B$23,MATCH(LARGE(Comparativo!$R$6:$R$23,A24),Comparativo!$R$6:$R$23,0)),"") | D24: =IFERROR(INDEX(Comparativo!$I$6:$I$23,MATCH(LARGE(Comparativo!$R$6:$R$23,A24),Comparativo!$R$6:$R$23,0)),"") | E24: =IFERROR(INDEX(Comparativo!$J$6:$J$23,MATCH(LARGE(Comparativo!$R$6:$R$23,A24),Comparativo!$R$6:$R$23,0)),"") | F24: =IFERROR(-IFERROR(INDEX(Comparativo!$K$6:$K$23,MATCH(LARGE(Comparativo!$R$6:$R$23,A24),Comparativo!$R$6:$R$23,0)),""),"") | G24: =IFERROR(F24/D24,"")
A25: 5 | B25: =IFERROR(INDEX(Comparativo!$D$6:$D$23,MATCH(LARGE(Comparativo!$R$6:$R$23,A25),Comparativo!$R$6:$R$23,0)),"") | C25: =IFERROR(INDEX(Comparativo!$B$6:$B$23,MATCH(LARGE(Comparativo!$R$6:$R$23,A25),Comparativo!$R$6:$R$23,0)),"") | D25: =IFERROR(INDEX(Comparativo!$I$6:$I$23,MATCH(LARGE(Comparativo!$R$6:$R$23,A25),Comparativo!$R$6:$R$23,0)),"") | E25: =IFERROR(INDEX(Comparativo!$J$6:$J$23,MATCH(LARGE(Comparativo!$R$6:$R$23,A25),Comparativo!$R$6:$R$23,0)),"") | F25: =IFERROR(-IFERROR(INDEX(Comparativo!$K$6:$K$23,MATCH(LARGE(Comparativo!$R$6:$R$23,A25),Comparativo!$R$6:$R$23,0)),""),"") | G25: =IFERROR(F25/D25,"")
A28: MAIORES DESVIOS DO ACUMULADO (top 5 acima do orçado)
A29: # | B29: Item | C29: Departamento | D29: Planejado acum. | E29: Realizado acum. | F29: Desvio (R$) | G29: Desvio (%)
A30: 1 | B30: =IFERROR(INDEX(Comparativo!$D$6:$D$23,MATCH(LARGE(Comparativo!$O$6:$O$23,A30),Comparativo!$O$6:$O$23,0)),"") | C30: =IFERROR(INDEX(Comparativo!$B$6:$B$23,MATCH(LARGE(Comparativo!$O$6:$O$23,A30),Comparativo!$O$6:$O$23,0)),"") | D30: =IFERROR(INDEX(Comparativo!$I$6:$I$23,MATCH(LARGE(Comparativo!$O$6:$O$23,A30),Comparativo!$O$6:$O$23,0)),"") | E30: =IFERROR(INDEX(Comparativo!$J$6:$J$23,MATCH(LARGE(Comparativo!$O$6:$O$23,A30),Comparativo!$O$6:$O$23,0)),"") | F30: =IFERROR(INDEX(Comparativo!$K$6:$K$23,MATCH(LARGE(Comparativo!$O$6:$O$23,A30),Comparativo!$O$6:$O$23,0)),"") | G30: =IFERROR(F30/D30,"")
A31: 2 | B31: =IFERROR(INDEX(Comparativo!$D$6:$D$23,MATCH(LARGE(Comparativo!$O$6:$O$23,A31),Comparativo!$O$6:$O$23,0)),"") | C31: =IFERROR(INDEX(Comparativo!$B$6:$B$23,MATCH(LARGE(Comparativo!$O$6:$O$23,A31),Comparativo!$O$6:$O$23,0)),"") | D31: =IFERROR(INDEX(Comparativo!$I$6:$I$23,MATCH(LARGE(Comparativo!$O$6:$O$23,A31),Comparativo!$O$6:$O$23,0)),"") | E31: =IFERROR(INDEX(Comparativo!$J$6:$J$23,MATCH(LARGE(Comparativo!$O$6:$O$23,A31),Comparativo!$O$6:$O$23,0)),"") | F31: =IFERROR(INDEX(Comparativo!$K$6:$K$23,MATCH(LARGE(Comparativo!$O$6:$O$23,A31),Comparativo!$O$6:$O$23,0)),"") | G31: =IFERROR(F31/D31,"")
A32: 3 | B32: =IFERROR(INDEX(Comparativo!$D$6:$D$23,MATCH(LARGE(Comparativo!$O$6:$O$23,A32),Comparativo!$O$6:$O$23,0)),"") | C32: =IFERROR(INDEX(Comparativo!$B$6:$B$23,MATCH(LARGE(Comparativo!$O$6:$O$23,A32),Comparativo!$O$6:$O$23,0)),"") | D32: =IFERROR(INDEX(Comparativo!$I$6:$I$23,MATCH(LARGE(Comparativo!$O$6:$O$23,A32),Comparativo!$O$6:$O$23,0)),"") | E32: =IFERROR(INDEX(Comparativo!$J$6:$J$23,MATCH(LARGE(Comparativo!$O$6:$O$23,A32),Comparativo!$O$6:$O$23,0)),"") | F32: =IFERROR(INDEX(Comparativo!$K$6:$K$23,MATCH(LARGE(Comparativo!$O$6:$O$23,A32),Comparativo!$O$6:$O$23,0)),"") | G32: =IFERROR(F32/D32,"")
A33: 4 | B33: =IFERROR(INDEX(Comparativo!$D$6:$D$23,MATCH(LARGE(Comparativo!$O$6:$O$23,A33),Comparativo!$O$6:$O$23,0)),"") | C33: =IFERROR(INDEX(Comparativo!$B$6:$B$23,MATCH(LARGE(Comparativo!$O$6:$O$23,A33),Comparativo!$O$6:$O$23,0)),"") | D33: =IFERROR(INDEX(Comparativo!$I$6:$I$23,MATCH(LARGE(Comparativo!$O$6:$O$23,A33),Comparativo!$O$6:$O$23,0)),"") | E33: =IFERROR(INDEX(Comparativo!$J$6:$J$23,MATCH(LARGE(Comparativo!$O$6:$O$23,A33),Comparativo!$O$6:$O$23,0)),"") | F33: =IFERROR(INDEX(Comparativo!$K$6:$K$23,MATCH(LARGE(Comparativo!$O$6:$O$23,A33),Comparativo!$O$6:$O$23,0)),"") | G33: =IFERROR(F33/D33,"")
A34: 5 | B34: =IFERROR(INDEX(Comparativo!$D$6:$D$23,MATCH(LARGE(Comparativo!$O$6:$O$23,A34),Comparativo!$O$6:$O$23,0)),"") | C34: =IFERROR(INDEX(Comparativo!$B$6:$B$23,MATCH(LARGE(Comparativo!$O$6:$O$23,A34),Comparativo!$O$6:$O$23,0)),"") | D34: =IFERROR(INDEX(Comparativo!$I$6:$I$23,MATCH(LARGE(Comparativo!$O$6:$O$23,A34),Comparativo!$O$6:$O$23,0)),"") | E34: =IFERROR(INDEX(Comparativo!$J$6:$J$23,MATCH(LARGE(Comparativo!$O$6:$O$23,A34),Comparativo!$O$6:$O$23,0)),"") | F34: =IFERROR(INDEX(Comparativo!$K$6:$K$23,MATCH(LARGE(Comparativo!$O$6:$O$23,A34),Comparativo!$O$6:$O$23,0)),"") | G34: =IFERROR(F34/D34,"")

Sheet Comparativo
A1: PLANEJADO x REALIZADO — linha a linha
A2: Escolha o mês de referência em B3. As colunas 'no mês' mostram só aquele mês; as colunas 'acumulado' somam de maio até o mês escolhido. Desvio positivo = gastou ACIMA do orçado.
A3: Mês de referência: | B3: Jun/26 | C3: Mês nº: | D3: =MATCH($B$3,Planejado!$H$4:$S$4,0)
A5: ID | B5: Departamento | C5: Bloco | D5: Descrição | E5: Plano de Contas | F5: Planejado no mês | G5: Realizado no mês | H5: Desvio no mês (R$) | I5: Planejado acum. | J5: Realizado acum. | K5: Desvio acum. (R$) | L5: Desvio acum. (%) | M5: % Executado | N5: Situação | O5: (aux ranking) | P5: (aux meses lançados) | Q5: (aux desvio comparável) | R5: (aux ranking economia) | S5: (aux planejado comparável)
A6: =Planejado!A5 | B6: =Planejado!B5 | C6: =Planejado!C5 | D6: =Planejado!D5 | E6: =Planejado!G5 | F6: =INDEX(Planejado!$H5:$S5,$D$3) | G6: =INDEX(Realizado!$H5:$S5,$D$3) | H6: =G6-F6 | I6: =SUMPRODUCT((COLUMN(Planejado!$H$4:$S$4)-COLUMN(Planejado!$H$4)+1<=$D$3)*Planejado!$H5:$S5) | J6: =SUMPRODUCT((COLUMN(Realizado!$H$4:$S$4)-COLUMN(Realizado!$H$4)+1<=$D$3)*Realizado!$H5:$S5) | K6: =J6-I6 | L6: =IFERROR(K6/I6,"") | M6: =IFERROR(J6/I6,"") | N6: =IF(P6=0,"Sem lançamento",IF(AND(I6=0,J6=0),"—",IF(I6=0,"Não orçado",IF(K6>0.05*I6,"Acima do orçado",IF(K6<-0.05*I6,"Abaixo do orçado","Dentro do orçado"))))) | O6: =IF(K6>1,K6+ROW()/1000000,"") | P6: =SUMPRODUCT((COLUMN(Realizado!$H$4:$S$4)-COLUMN(Realizado!$H$4)+1<=$D$3)*(Realizado!$H5:$S5<>"")) | Q6: =IF(P6=0,"",K6) | R6: =IF(AND(Q6<>"",Q6<-1),-Q6+ROW()/1000000,"") | S6: =IF(Q6="","",I6)
A7: =Planejado!A6 | B7: =Planejado!B6 | C7: =Planejado!C6 | D7: =Planejado!D6 | E7: =Planejado!G6 | F7: =INDEX(Planejado!$H6:$S6,$D$3) | G7: =INDEX(Realizado!$H6:$S6,$D$3) | H7: =G7-F7 | I7: =SUMPRODUCT((COLUMN(Planejado!$H$4:$S$4)-COLUMN(Planejado!$H$4)+1<=$D$3)*Planejado!$H6:$S6) | J7: =SUMPRODUCT((COLUMN(Realizado!$H$4:$S$4)-COLUMN(Realizado!$H$4)+1<=$D$3)*Realizado!$H6:$S6) | K7: =J7-I7 | L7: =IFERROR(K7/I7,"") | M7: =IFERROR(J7/I7,"") | N7: =IF(P7=0,"Sem lançamento",IF(AND(I7=0,J7=0),"—",IF(I7=0,"Não orçado",IF(K7>0.05*I7,"Acima do orçado",IF(K7<-0.05*I7,"Abaixo do orçado","Dentro do orçado"))))) | O7: =IF(K7>1,K7+ROW()/1000000,"") | P7: =SUMPRODUCT((COLUMN(Realizado!$H$4:$S$4)-COLUMN(Realizado!$H$4)+1<=$D$3)*(Realizado!$H6:$S6<>"")) | Q7: =IF(P7=0,"",K7) | R7: =IF(AND(Q7<>"",Q7<-1),-Q7+ROW()/1000000,"") | S7: =IF(Q7="","",I7)
A8: =Planejado!A7 | B8: =Planejado!B7 | C8: =Planejado!C7 | D8: =Planejado!D7 | E8: =Planejado!G7 | F8: =INDEX(Planejado!$H7:$S7,$D$3) | G8: =INDEX(Realizado!$H7:$S7,$D$3) | H8: =G8-F8 | I8: =SUMPRODUCT((COLUMN(Planejado!$H$4:$S$4)-COLUMN(Planejado!$H$4)+1<=$D$3)*Planejado!$H7:$S7) | J8: =SUMPRODUCT((COLUMN(Realizado!$H$4:$S$4)-COLUMN(Realizado!$H$4)+1<=$D$3)*Realizado!$H7:$S7) | K8: =J8-I8 | L8: =IFERROR(K8/I8,"") | M8: =IFERROR(J8/I8,"") | N8: =IF(P8=0,"Sem lançamento",IF(AND(I8=0,J8=0),"—",IF(I8=0,"Não orçado",IF(K8>0.05*I8,"Acima do orçado",IF(K8<-0.05*I8,"Abaixo do orçado","Dentro do orçado"))))) | O8: =IF(K8>1,K8+ROW()/1000000,"") | P8: =SUMPRODUCT((COLUMN(Realizado!$H$4:$S$4)-COLUMN(Realizado!$H$4)+1<=$D$3)*(Realizado!$H7:$S7<>"")) | Q8: =IF(P8=0,"",K8) | R8: =IF(AND(Q8<>"",Q8<-1),-Q8+ROW()/1000000,"") | S8: =IF(Q8="","",I8)
A9: =Planejado!A8 | B9: =Planejado!B8 | C9: =Planejado!C8 | D9: =Planejado!D8 | E9: =Planejado!G8 | F9: =INDEX(Planejado!$H8:$S8,$D$3) | G9: =INDEX(Realizado!$H8:$S8,$D$3) | H9: =G9-F9 | I9: =SUMPRODUCT((COLUMN(Planejado!$H$4:$S$4)-COLUMN(Planejado!$H$4)+1<=$D$3)*Planejado!$H8:$S8) | J9: =SUMPRODUCT((COLUMN(Realizado!$H$4:$S$4)-COLUMN(Realizado!$H$4)+1<=$D$3)*Realizado!$H8:$S8) | K9: =J9-I9 | L9: =IFERROR(K9/I9,"") | M9: =IFERROR(J9/I9,"") | N9: =IF(P9=0,"Sem lançamento",IF(AND(I9=0,J9=0),"—",IF(I9=0,"Não orçado",IF(K9>0.05*I9,"Acima do orçado",IF(K9<-0.05*I9,"Abaixo do orçado","Dentro do orçado"))))) | O9: =IF(K9>1,K9+ROW()/1000000,"") | P9: =SUMPRODUCT((COLUMN(Realizado!$H$4:$S$4)-COLUMN(Realizado!$H$4)+1<=$D$3)*(Realizado!$H8:$S8<>"")) | Q9: =IF(P9=0,"",K9) | R9: =IF(AND(Q9<>"",Q9<-1),-Q9+ROW()/1000000,"") | S9: =IF(Q9="","",I9)
A10: =Planejado!A9 | B10: =Planejado!B9 | C10: =Planejado!C9 | D10: =Planejado!D9 | E10: =Planejado!G9 | F10: =INDEX(Planejado!$H9:$S9,$D$3) | G10: =INDEX(Realizado!$H9:$S9,$D$3) | H10: =G10-F10 | I10: =SUMPRODUCT((COLUMN(Planejado!$H$4:$S$4)-COLUMN(Planejado!$H$4)+1<=$D$3)*Planejado!$H9:$S9) | J10: =SUMPRODUCT((COLUMN(Realizado!$H$4:$S$4)-COLUMN(Realizado!$H$4)+1<=$D$3)*Realizado!$H9:$S9) | K10: =J10-I10 | L10: =IFERROR(K10/I10,"") | M10: =IFERROR(J10/I10,"") | N10: =IF(P10=0,"Sem lançamento",IF(AND(I10=0,J10=0),"—",IF(I10=0,"Não orçado",IF(K10>0.05*I10,"Acima do orçado",IF(K10<-0.05*I10,"Abaixo do orçado","Dentro do orçado"))))) | O10: =IF(K10>1,K10+ROW()/1000000,"") | P10: =SUMPRODUCT((COLUMN(Realizado!$H$4:$S$4)-COLUMN(Realizado!$H$4)+1<=$D$3)*(Realizado!$H9:$S9<>"")) | Q10: =IF(P10=0,"",K10) | R10: =IF(AND(Q10<>"",Q10<-1),-Q10+ROW()/1000000,"") | S10: =IF(Q10="","",I10)
A11: =Planejado!A10 | B11: =Planejado!B10 | C11: =Planejado!C10 | D11: =Planejado!D10 | E11: =Planejado!G10 | F11: =INDEX(Planejado!$H10:$S10,$D$3) | G11: =INDEX(Realizado!$H10:$S10,$D$3) | H11: =G11-F11 | I11: =SUMPRODUCT((COLUMN(Planejado!$H$4:$S$4)-COLUMN(Planejado!$H$4)+1<=$D$3)*Planejado!$H10:$S10) | J11: =SUMPRODUCT((COLUMN(Realizado!$H$4:$S$4)-COLUMN(Realizado!$H$4)+1<=$D$3)*Realizado!$H10:$S10) | K11: =J11-I11 | L11: =IFERROR(K11/I11,"") | M11: =IFERROR(J11/I11,"") | N11: =IF(P11=0,"Sem lançamento",IF(AND(I11=0,J11=0),"—",IF(I11=0,"Não orçado",IF(K11>0.05*I11,"Acima do orçado",IF(K11<-0.05*I11,"Abaixo do orçado","Dentro do orçado"))))) | O11: =IF(K11>1,K11+ROW()/1000000,"") | P11: =SUMPRODUCT((COLUMN(Realizado!$H$4:$S$4)-COLUMN(Realizado!$H$4)+1<=$D$3)*(Realizado!$H10:$S10<>"")) | Q11: =IF(P11=0,"",K11) | R11: =IF(AND(Q11<>"",Q11<-1),-Q11+ROW()/1000000,"") | S11: =IF(Q11="","",I11)
A12: =Planejado!A11 | B12: =Planejado!B11 | C12: =Planejado!C11 | D12: =Planejado!D11 | E12: =Planejado!G11 | F12: =INDEX(Planejado!$H11:$S11,$D$3) | G12: =INDEX(Realizado!$H11:$S11,$D$3) | H12: =G12-F12 | I12: =SUMPRODUCT((COLUMN(Planejado!$H$4:$S$4)-COLUMN(Planejado!$H$4)+1<=$D$3)*Planejado!$H11:$S11) | J12: =SUMPRODUCT((COLUMN(Realizado!$H$4:$S$4)-COLUMN(Realizado!$H$4)+1<=$D$3)*Realizado!$H11:$S11) | K12: =J12-I12 | L12: =IFERROR(K12/I12,"") | M12: =IFERROR(J12/I12,"") | N12: =IF(P12=0,"Sem lançamento",IF(AND(I12=0,J12=0),"—",IF(I12=0,"Não orçado",IF(K12>0.05*I12,"Acima do orçado",IF(K12<-0.05*I12,"Abaixo do orçado","Dentro do orçado"))))) | O12: =IF(K12>1,K12+ROW()/1000000,"") | P12: =SUMPRODUCT((COLUMN(Realizado!$H$4:$S$4)-COLUMN(Realizado!$H$4)+1<=$D$3)*(Realizado!$H11:$S11<>"")) | Q12: =IF(P12=0,"",K12) | R12: =IF(AND(Q12<>"",Q12<-1),-Q12+ROW()/1000000,"") | S12: =IF(Q12="","",I12)
A13: =Planejado!A12 | B13: =Planejado!B12 | C13: =Planejado!C12 | D13: =Planejado!D12 | E13: =Planejado!G12 | F13: =INDEX(Planejado!$H12:$S12,$D$3) | G13: =INDEX(Realizado!$H12:$S12,$D$3) | H13: =G13-F13 | I13: =SUMPRODUCT((COLUMN(Planejado!$H$4:$S$4)-COLUMN(Planejado!$H$4)+1<=$D$3)*Planejado!$H12:$S12) | J13: =SUMPRODUCT((COLUMN(Realizado!$H$4:$S$4)-COLUMN(Realizado!$H$4)+1<=$D$3)*Realizado!$H12:$S12) | K13: =J13-I13 | L13: =IFERROR(K13/I13,"") | M13: =IFERROR(J13/I13,"") | N13: =IF(P13=0,"Sem lançamento",IF(AND(I13=0,J13=0),"—",IF(I13=0,"Não orçado",IF(K13>0.05*I13,"Acima do orçado",IF(K13<-0.05*I13,"Abaixo do orçado","Dentro do orçado"))))) | O13: =IF(K13>1,K13+ROW()/1000000,"") | P13: =SUMPRODUCT((COLUMN(Realizado!$H$4:$S$4)-COLUMN(Realizado!$H$4)+1<=$D$3)*(Realizado!$H12:$S12<>"")) | Q13: =IF(P13=0,"",K13) | R13: =IF(AND(Q13<>"",Q13<-1),-Q13+ROW()/1000000,"") | S13: =IF(Q13="","",I13)
A14: =Planejado!A13 | B14: =Planejado!B13 | C14: =Planejado!C13 | D14: =Planejado!D13 | E14: =Planejado!G13 | F14: =INDEX(Planejado!$H13:$S13,$D$3) | G14: =INDEX(Realizado!$H13:$S13,$D$3) | H14: =G14-F14 | I14: =SUMPRODUCT((COLUMN(Planejado!$H$4:$S$4)-COLUMN(Planejado!$H$4)+1<=$D$3)*Planejado!$H13:$S13) | J14: =SUMPRODUCT((COLUMN(Realizado!$H$4:$S$4)-COLUMN(Realizado!$H$4)+1<=$D$3)*Realizado!$H13:$S13) | K14: =J14-I14 | L14: =IFERROR(K14/I14,"") | M14: =IFERROR(J14/I14,"") | N14: =IF(P14=0,"Sem lançamento",IF(AND(I14=0,J14=0),"—",IF(I14=0,"Não orçado",IF(K14>0.05*I14,"Acima do orçado",IF(K14<-0.05*I14,"Abaixo do orçado","Dentro do orçado"))))) | O14: =IF(K14>1,K14+ROW()/1000000,"") | P14: =SUMPRODUCT((COLUMN(Realizado!$H$4:$S$4)-COLUMN(Realizado!$H$4)+1<=$D$3)*(Realizado!$H13:$S13<>"")) | Q14: =IF(P14=0,"",K14) | R14: =IF(AND(Q14<>"",Q14<-1),-Q14+ROW()/1000000,"") | S14: =IF(Q14="","",I14)
A15: =Planejado!A14 | B15: =Planejado!B14 | C15: =Planejado!C14 | D15: =Planejado!D14 | E15: =Planejado!G14 | F15: =INDEX(Planejado!$H14:$S14,$D$3) | G15: =INDEX(Realizado!$H14:$S14,$D$3) | H15: =G15-F15 | I15: =SUMPRODUCT((COLUMN(Planejado!$H$4:$S$4)-COLUMN(Planejado!$H$4)+1<=$D$3)*Planejado!$H14:$S14) | J15: =SUMPRODUCT((COLUMN(Realizado!$H$4:$S$4)-COLUMN(Realizado!$H$4)+1<=$D$3)*Realizado!$H14:$S14) | K15: =J15-I15 | L15: =IFERROR(K15/I15,"") | M15: =IFERROR(J15/I15,"") | N15: =IF(P15=0,"Sem lançamento",IF(AND(I15=0,J15=0),"—",IF(I15=0,"Não orçado",IF(K15>0.05*I15,"Acima do orçado",IF(K15<-0.05*I15,"Abaixo do orçado","Dentro do orçado"))))) | O15: =IF(K15>1,K15+ROW()/1000000,"") | P15: =SUMPRODUCT((COLUMN(Realizado!$H$4:$S$4)-COLUMN(Realizado!$H$4)+1<=$D$3)*(Realizado!$H14:$S14<>"")) | Q15: =IF(P15=0,"",K15) | R15: =IF(AND(Q15<>"",Q15<-1),-Q15+ROW()/1000000,"") | S15: =IF(Q15="","",I15)
A16: =Planejado!A15 | B16: =Planejado!B15 | C16: =Planejado!C15 | D16: =Planejado!D15 | E16: =Planejado!G15 | F16: =INDEX(Planejado!$H15:$S15,$D$3) | G16: =INDEX(Realizado!$H15:$S15,$D$3) | H16: =G16-F16 | I16: =SUMPRODUCT((COLUMN(Planejado!$H$4:$S$4)-COLUMN(Planejado!$H$4)+1<=$D$3)*Planejado!$H15:$S15) | J16: =SUMPRODUCT((COLUMN(Realizado!$H$4:$S$4)-COLUMN(Realizado!$H$4)+1<=$D$3)*Realizado!$H15:$S15) | K16: =J16-I16 | L16: =IFERROR(K16/I16,"") | M16: =IFERROR(J16/I16,"") | N16: =IF(P16=0,"Sem lançamento",IF(AND(I16=0,J16=0),"—",IF(I16=0,"Não orçado",IF(K16>0.05*I16,"Acima do orçado",IF(K16<-0.05*I16,"Abaixo do orçado","Dentro do orçado"))))) | O16: =IF(K16>1,K16+ROW()/1000000,"") | P16: =SUMPRODUCT((COLUMN(Realizado!$H$4:$S$4)-COLUMN(Realizado!$H$4)+1<=$D$3)*(Realizado!$H15:$S15<>"")) | Q16: =IF(P16=0,"",K16) | R16: =IF(AND(Q16<>"",Q16<-1),-Q16+ROW()/1000000,"") | S16: =IF(Q16="","",I16)
A17: =Planejado!A16 | B17: =Planejado!B16 | C17: =Planejado!C16 | D17: =Planejado!D16 | E17: =Planejado!G16 | F17: =INDEX(Planejado!$H16:$S16,$D$3) | G17: =INDEX(Realizado!$H16:$S16,$D$3) | H17: =G17-F17 | I17: =SUMPRODUCT((COLUMN(Planejado!$H$4:$S$4)-COLUMN(Planejado!$H$4)+1<=$D$3)*Planejado!$H16:$S16) | J17: =SUMPRODUCT((COLUMN(Realizado!$H$4:$S$4)-COLUMN(Realizado!$H$4)+1<=$D$3)*Realizado!$H16:$S16) | K17: =J17-I17 | L17: =IFERROR(K17/I17,"") | M17: =IFERROR(J17/I17,"") | N17: =IF(P17=0,"Sem lançamento",IF(AND(I17=0,J17=0),"—",IF(I17=0,"Não orçado",IF(K17>0.05*I17,"Acima do orçado",IF(K17<-0.05*I17,"Abaixo do orçado","Dentro do orçado"))))) | O17: =IF(K17>1,K17+ROW()/1000000,"") | P17: =SUMPRODUCT((COLUMN(Realizado!$H$4:$S$4)-COLUMN(Realizado!$H$4)+1<=$D$3)*(Realizado!$H16:$S16<>"")) | Q17: =IF(P17=0,"",K17) | R17: =IF(AND(Q17<>"",Q17<-1),-Q17+ROW()/1000000,"") | S17: =IF(Q17="","",I17)
... A23: =Planejado!A22 | B23: =Planejado!B22 | C23: =Planejado!C22 | D23: =Planejado!D22 | E23: =Planejado!G22 | F23: =INDEX(Planejado!$H22:$S22,$D$3) | G23: =INDEX(Realizado!$H22:$S22,$D$3) | H23: =G23-F23 | I23: =SUMPRODUCT((COLUMN(Planejado!$H$4:$S$4)-COLUMN(Planejado!$H$4)+1<=$D$3)*Planejado!$H22:$S22) | J23: =SUMPRODUCT((COLUMN(Realizado!$H$4:$S$4)-COLUMN(Realizado!$H$4)+1<=$D$3)*Realizado!$H22:$S22) | K23: =J23-I23 | L23: =IFERROR(K23/I23,"") | M23: =IFERROR(J23/I23,"") | N23: =IF(P23=0,"Sem lançamento",IF(AND(I23=0,J23=0),"—",IF(I23=0,"Não orçado",IF(K23>0.05*I23,"Acima do orçado",IF(K23<-0.05*I23,"Abaixo do orçado","Dentro do orçado"))))) | O23: =IF(K23>1,K23+ROW()/1000000,"") | P23: =SUMPRODUCT((COLUMN(Realizado!$H$4:$S$4)-COLUMN(Realizado!$H$4)+1<=$D$3)*(Realizado!$H22:$S22<>"")) | Q23: =IF(P23=0,"",K23) | R23: =IF(AND(Q23<>"",Q23<-1),-Q23+ROW()/1000000,"") | S23: =IF(Q23="","",I23)
A34: TOTAL GERAL | F34: =SUM(F6:F23) | G34: =SUM(G6:G23) | H34: =SUM(H6:H23) | I34: =SUM(I6:I23) | J34: =SUM(J6:J23) | K34: =SUM(K6:K23) | L34: =IFERROR(K34/I34,"") | M34: =IFERROR(J34/I34,"")

Sheet Planejado
A1: ORÇAMENTO PLANEJADO 2026 — TI
A2: Base: janeiro a dezembro/2026 (12 meses). CLT com encargos de folha + benefícios inclusos. Esta aba é a referência — altere aqui apenas se o orçamento for oficialmente revisado.
A4: ID | B4: Departamento | C4: Bloco | D4: Descrição | E4: Detalhe / Observação | F4: Vínculo | G4: Plano de Contas | H4: Jan/26 | I4: Fev/26 | J4: Mar/26 | K4: Abr/26 | L4: Mai/26 | M4: Jun/26 | N4: Jul/26 | O4: Ago/26 | P4: Set/26 | Q4: Out/26 | R4: Nov/26 | S4: Dez/26 | T4: TOTAL DO ANO
A5: TI-E01 | B5: TI | C5: Equipe | D5: Vinicius Di Franco | E5: Analista Administrativo — suporte ao usuário, rotina administrativa do orçamento e apoio operacional ao desenvolvimento conduzido pelo consultor. Orçado pelo custo total (encargos de folha + benefícios). Salário bruto: R$ 2.570,52/mês até jul/26 e R$ 3.070,52 a partir de 05/08/26, aumento absorvido pela folga do envelope | F5: CLT | G5: Pessoal - CLT | H5: 5416.525 | I5: 5416.525 | J5: 5416.525 | K5: 5416.525 | L5: 5416.525 | M5: 5416.525 | N5: 5416.525 | O5: 5416.525 | P5: 5416.525 | Q5: 5416.525 | R5: 5416.525 | S5: 5416.525 | T5: =SUM(H5:S5)
A6: TI-E02 | B6: TI | C6: Equipe | D6: Elias Benedito | E6: Suporte Técnico Terceirizado — R$ 1.065/mês até ago/26; R$ 603,30 a partir de set/26 (renegociação) | F6: PJ | G6: Pessoal - PJ | H6: 1065 | I6: 1065 | J6: 1065 | K6: 1065 | L6: 1065 | M6: 1065 | N6: 1065 | O6: 1065 | P6: 603.3 | Q6: 603.3 | R6: 603.3 | S6: 603.3 | T6: =SUM(H6:S6)
A7: TI-E03 | B7: TI | C7: Equipe | D7: Jonathan — consultor (desde abr/26) | E7: Consultor/desenvolvedor, 3 dias por semana (104 h/mês) desde abr/26. Orçado em R$ 10.000/mês desde jan/26; a contratação foi segurada por três meses. Credor no SIENGE: J H ALVES — MONITOR REMOTO | F7: PJ | G7: Pessoal - PJ | H7: 10000 | I7: 10000 | J7: 10000 | K7: 10000 | L7: 10000 | M7: 10000 | N7: 10000 | O7: 10000 | P7: 10000 | Q7: 10000 | R7: 10000 | S7: 10000 | T7: =SUM(H7:S7)
A8: TI-E04 | B8: TI | C8: Equipe | D8: Monitor Remoto — serviços esporádicos (até mar/26) | E8: Mesmo prestador do TI-E03, em vínculo anterior: serviços esporádicos prestados de fora, encerrados quando ele passou a atuar como consultor fixo em abr/26. Não constava na ficha de orçamento | F8: PJ | G8: Pessoal - PJ | H8: 0 | I8: 0 | J8: 0 | K8: 0 | L8: 0 | M8: 0 | N8: 0 | O8: 0 | P8: 0 | Q8: 0 | R8: 0 | S8: 0 | T8: =SUM(H8:S8)
A9: TI-D01 | B9: TI | C9: Despesas | D9: Peças de Manutenção | E9: Tela, teclado, carcaça, mouses de reposição, carregadores etc. | G9: Equipamentos Eletrônicos Diversos | H9: 810 | I9: 810 | J9: 810 | K9: 810 | L9: 810 | M9: 810 | N9: 810 | O9: 810 | P9: 810 | Q9: 810 | R9: 810 | S9: 810 | T9: =SUM(H9:S9)
A10: TI-D02 | B10: TI | C10: Despesas | D10: Backup em Nuvem | E10: Serviço de backup em nuvem para servidor — RATEIO A DEFINIR | G10: Licenças de Softwares | H10: 825 | I10: 825 | J10: 825 | K10: 825 | L10: 825 | M10: 825 | N10: 825 | O10: 825 | P10: 825 | Q10: 825 | R10: 825 | S10: 825 | T10: =SUM(H10:S10)
A11: TI-D03 | B11: TI | C11: Despesas | D11: Inteligência Artificial (Adapta) | E11: Plataforma de IA para utilização de agentes — RATEIO A DEFINIR. Pagamentos reais de R$ 575/mês estão lançados no centro de custo Jurídico por engano (ver pendência Q) | G11: Licenças de Softwares | H11: 1300 | I11: 1300 | J11: 1300 | K11: 1300 | L11: 1300 | M11: 1300 | N11: 1600 | O11: 1600 | P11: 1600 | Q11: 1600 | R11: 1600 | S11: 1600 | T11: =SUM(H11:S11)
A12: TI-D04 | B12: TI | C12: Despesas | D12: Antivírus | E12: Proteção para equipamentos — RATEIO A DEFINIR | G12: Licenças de Softwares | H12: 240 | I12: 240 | J12: 240 | K12: 240 | L12: 240 | M12: 240 | N12: 240 | O12: 240 | P12: 240 | Q12: 240 | R12: 240 | S12: 240 | T12: =SUM(H12:S12)
A13: TI-D05 | B13: TI | C13: Despesas | D13: Pacote Office 365 | E13: Licenças de software (conferir nº de licenças x usuários) — RATEIO A DEFINIR | G13: Licenças de Softwares | H13: 375 | I13: 375 | J13: 375 | K13: 375 | L13: 375 | M13: 375 | N13: 375 | O13: 375 | P13: 375 | Q13: 375 | R13: 375 | S13: 375 | T13: =SUM(H13:S13)
A14: TI-D06 | B14: TI | C14: Despesas | D14: Projeto Sala de Reunião — itens funcionais | E14: Câmeras, microfones e cadeiras. DECIDIDO executar só o funcional; cafeteira, copos, canetas e blocos personalizados saem para o Administrativo. Valor a rever quando vier a quebra entre funcional e consumo | G14: Móveis e Utensílios | H14: 2800 | I14: 2800 | J14: 2800 | K14: 2800 | L14: 2800 | M14: 2800 | N14: 2800 | O14: 2800 | P14: 2800 | Q14: 2800 | R14: 2800 | S14: 2800 | T14: =SUM(H14:S14)
A15: TI-D07 | B15: TI | C15: Despesas | D15: Cursos e Treinamentos | G15: Custeio de Treinamento | H15: 200 | I15: 200 | J15: 200 | K15: 200 | L15: 200 | M15: 200 | N15: 200 | O15: 200 | P15: 200 | Q15: 200 | R15: 200 | S15: 200 | T15: =SUM(H15:S15)
A16: TI-D08 | B16: TI | C16: Despesas | D16: Aplicativo de Gravação de Reunião | G16: Licenças de Softwares | H16: 220 | I16: 220 | J16: 220 | K16: 220 | L16: 220 | M16: 220 | N16: 220 | O16: 220 | P16: 220 | Q16: 220 | R16: 220 | S16: 220 | T16: =SUM(H16:S16)
A17: TI-D10 | B17: TI | C17: Despesas | D17: Claude | E17: Ferramenta de IA — não constava na ficha. Planejado a definir com a diretoria. RATEIO A DEFINIR: uso transversal entre as áreas | G17: Licenças de Softwares | H17: 0 | I17: 0 | J17: 0 | K17: 0 | L17: 0 | M17: 0 | N17: 0 | O17: 0 | P17: 0 | Q17: 0 | R17: 0 | S17: 0 | T17: =SUM(H17:S17)
A18: TI-D11 | B18: TI | C18: Despesas | D18: GPT | E18: Ferramenta de IA — não constava na ficha. Planejado a definir com a diretoria. RATEIO A DEFINIR: uso transversal entre as áreas | G18: Licenças de Softwares | H18: 0 | I18: 0 | J18: 0 | K18: 0 | L18: 0 | M18: 0 | N18: 0 | O18: 0 | P18: 0 | Q18: 0 | R18: 0 | S18: 0 | T18: =SUM(H18:S18)
A19: TI-D12 | B19: TI | C19: Despesas | D19: Adapta One | E19: Ferramenta de IA — não constava na ficha. Planejado a definir com a diretoria. RATEIO A DEFINIR: uso transversal entre as áreas. CONFERIR sobreposição com a linha 'Inteligência Artificial (Adapta)' | G19: Licenças de Softwares | H19: 0 | I19: 0 | J19: 0 | K19: 0 | L19: 0 | M19: 0 | N19: 0 | O19: 0 | P19: 0 | Q19: 0 | R19: 0 | S19: 0 | T19: =SUM(H19:S19)
A20: TI-D13 | B20: TI | C20: Despesas | D20: Adapta Skip | E20: Ferramenta de IA — não constava na ficha. Planejado a definir com a diretoria. RATEIO A DEFINIR: uso transversal entre as áreas. CONFERIR o nome exato do produto e a sobreposição com 'Inteligência Artificial (Adapta)' | G20: Licenças de Softwares | H20: 0 | I20: 0 | J20: 0 | K20: 0 | L20: 0 | M20: 0 | N20: 0 | O20: 0 | P20: 0 | Q20: 0 | R20: 0 | S20: 0 | T20: =SUM(H20:S20)
A21: TI-D14 | B21: TI | C21: Despesas | D21: AnyDesk | E21: Licença de acesso remoto — contratação prevista, não constava na ficha. Valor e mês de início a definir. CONFERIR sobreposição com o serviço de monitoramento remoto já contratado (J H Alves) | G21: Licenças de Softwares | H21: 0 | I21: 0 | J21: 0 | K21: 0 | L21: 0 | M21: 0 | N21: 0 | O21: 0 | P21: 0 | Q21: 0 | R21: 0 | S21: 0 | T21: =SUM(H21:S21)
A22: TI-D09 | B22: TI | C22: Despesas | D22: Bonificação do time | E22: Cumprimento de prazos e participação em projetos — CONFIRMAR se houve parcela no 1º quadrimestre | G22: Prêmios | H22: 0 | I22: 0 | J22: 0 | K22: 0 | L22: 0 | M22: 0 | N22: 0 | O22: 2400 | P22: 0 | Q22: 0 | R22: 0 | S22: 3600 | T22: =SUM(H22:S22)
A23: TOTAL GERAL | H23: =SUM(H5:H22) | I23: =SUM(I5:I22) | J23: =SUM(J5:J22) | K23: =SUM(K5:K22) | L23: =SUM(L5:L22) | M23: =SUM(M5:M22) | N23: =SUM(N5:N22) | O23: =SUM(O5:O22) | ... T23: =SUM(T5:T22)

Sheet Realizado
A1: REALIZADO 2026 — TI
A2: Preencha SOMENTE as células amarelas (meses). As colunas de identificação vêm da aba Planejado. Lance o valor efetivamente pago/competência do mês. Mês sem gasto: digite 0 para diferenciar de 'ainda não lançado'.
A4: ID | B4: Departamento | C4: Bloco | D4: Descrição | E4: Detalhe / Observação | F4: Vínculo | G4: Plano de Contas | H4: Jan/26 | I4: Fev/26 | J4: Mar/26 | K4: Abr/26 | L4: Mai/26 | M4: Jun/26 | N4: Jul/26 | O4: Ago/26 | P4: Set/26 | Q4: Out/26 | R4: Nov/26 | S4: Dez/26 | T4: TOTAL REALIZADO | U4: Fonte do dado | V4: Observações do mês
A5: =Planejado!A5 | B5: =Planejado!B5 | C5: =Planejado!C5 | D5: =Planejado!D5 | E5: =Planejado!E5 | F5: =Planejado!F5 | G5: =Planejado!G5 | T5: =SUM(H5:S5) | V5: PREENCHER com o CUSTO TOTAL. Bruto: R$ 2.570,52/mês até jul e R$ 3.070,52 de ago — faltam encargos e benefícios
A6: =Planejado!A6 | B6: =Planejado!B6 | C6: =Planejado!C6 | D6: =Planejado!D6 | E6: =Planejado!E6 | F6: =Planejado!F6 | G6: =Planejado!G6 | H6: 0 | I6: 0 | J6: 0 | K6: 0 | L6: 0 | M6: 0 | T6: =SUM(H6:S6) | U6: Gestora, 05/08/26 — competência | V6: Sem acionamento no período — confirmar se o contrato segue ativo
A7: =Planejado!A7 | B7: =Planejado!B7 | C7: =Planejado!C7 | D7: =Planejado!D7 | E7: =Planejado!E7 | F7: =Planejado!F7 | G7: =Planejado!G7 | H7: 0 | I7: 0 | J7: 0 | K7: 3723.62 | L7: 6173.37 | M7: 6300 | T7: =SUM(H7:S7) | U7: Extrato do financeiro | V7: Serviço de abr, mai e jun (pagos em 01/05, 01/06 e 01/07). Zero em jan–mar: contratação segurada — bate com a entrada em abr
A8: =Planejado!A8 | B8: =Planejado!B8 | C8: =Planejado!C8 | D8: =Planejado!D8 | E8: =Planejado!E8 | F8: =Planejado!F8 | G8: =Planejado!G8 | H8: 0 | I8: 0 | J8: 0 | K8: 0 | L8: 0 | M8: 0 | N8: 0 | O8: 0 | P8: 0 | Q8: 0 | R8: 0 | S8: 0 | T8: =SUM(H8:S8) | U8: Extrato do financeiro | V8: Zero no exercício: o pagamento de R$ 4.311,56 em 19/01 (NFS.70) era serviço de dez/25 e, por competência, não pertence a 2026. Vínculo encerrado com a entrada como consultor fixo
A9: =Planejado!A9 | B9: =Planejado!B9 | C9: =Planejado!C9 | D9: =Planejado!D9 | E9: =Planejado!E9 | F9: =Planejado!F9 | G9: =Planejado!G9 | T9: =SUM(H9:S9)
A10: =Planejado!A10 | B10: =Planejado!B10 | C10: =Planejado!C10 | D10: =Planejado!D10 | E10: =Planejado!E10 | F10: =Planejado!F10 | G10: =Planejado!G10 | T10: =SUM(H10:S10)
A11: =Planejado!A11 | B11: =Planejado!B11 | C11: =Planejado!C11 | D11: =Planejado!D11 | E11: =Planejado!E11 | F11: =Planejado!F11 | G11: =Planejado!G11 | T11: =SUM(H11:S11)
A12: =Planejado!A12 | B12: =Planejado!B12 | C12: =Planejado!C12 | D12: =Planejado!D12 | E12: =Planejado!E12 | F12: =Planejado!F12 | G12: =Planejado!G12 | T12: =SUM(H12:S12)
A13: =Planejado!A13 | B13: =Planejado!B13 | C13: =Planejado!C13 | D13: =Planejado!D13 | E13: =Planejado!E13 | F13: =Planejado!F13 | G13: =Planejado!G13 | T13: =SUM(H13:S13)
A14: =Planejado!A14 | B14: =Planejado!B14 | C14: =Planejado!C14 | D14: =Planejado!D14 | E14: =Planejado!E14 | F14: =Planejado!F14 | G14: =Planejado!G14 | T14: =SUM(H14:S14)
A15: =Planejado!A15 | B15: =Planejado!B15 | C15: =Planejado!C15 | D15: =Planejado!D15 | E15: =Planejado!E15 | F15: =Planejado!F15 | G15: =Planejado!G15 | T15: =SUM(H15:S15)
A16: =Planejado!A16 | B16: =Planejado!B16 | C16: =Planejado!C16 | D16: =Planejado!D16 | E16: =Planejado!E16 | F16: =Planejado!F16 | G16: =Planejado!G16 | T16: =SUM(H16:S16)
A17: =Planejado!A17 | B17: =Planejado!B17 | C17: =Planejado!C17 | D17: =Planejado!D17 | E17: =Planejado!E17 | F17: =Planejado!F17 | G17: =Planejado!G17 | T17: =SUM(H17:S17)
A18: =Planejado!A18 | B18: =Planejado!B18 | C18: =Planejado!C18 | D18: =Planejado!D18 | E18: =Planejado!E18 | F18: =Planejado!F18 | G18: =Planejado!G18 | T18: =SUM(H18:S18)
A19: =Planejado!A19 | B19: =Planejado!B19 | C19: =Planejado!C19 | D19: =Planejado!D19 | E19: =Planejado!E19 | F19: =Planejado!F19 | G19: =Planejado!G19 | T19: =SUM(H19:S19)
A20: =Planejado!A20 | B20: =Planejado!B20 | C20: =Planejado!C20 | D20: =Planejado!D20 | E20: =Planejado!E20 | F20: =Planejado!F20 | G20: =Planejado!G20 | T20: =SUM(H20:S20)
A21: =Planejado!A21 | B21: =Planejado!B21 | C21: =Planejado!C21 | D21: =Planejado!D21 | E21: =Planejado!E21 | F21: =Planejado!F21 | G21: =Planejado!G21 | H21: 0 | I21: 0 | J21: 0 | K21: 0 | L21: 0 | M21: 0 | N21: 0 | T21: =SUM(H21:S21) | U21: Gestora, 05/08/26 — competência | V21: Ainda não contratado — sem custo até jul/26
A22: =Planejado!A22 | B22: =Planejado!B22 | C22: =Planejado!C22 | D22: =Planejado!D22 | E22: =Planejado!E22 | F22: =Planejado!F22 | G22: =Planejado!G22 | T22: =SUM(H22:S22)
A23: TOTAL GERAL | H23: =SUM(H5:H22) | I23: =SUM(I5:I22) | J23: =SUM(J5:J22) | K23: =SUM(K5:K22) | L23: =SUM(L5:L22) | M23: =SUM(M5:M22) | N23: =SUM(N5:N22) | O23: =SUM(O5:O22) | ... T23: =SUM(T5:T22)

Sheet Evolução Mensal
A1: EVOLUÇÃO MENSAL — Planejado x Realizado
A2: Visão mês a mês do consolidado e por departamento. Alimenta gráficos e a leitura de tendência.
A4: Mês | B4: TI Plan. | C4: TI Real. | D4: Total Plan. | E4: Total Real. | F4: Desvio do mês (R$) | G4: Planejado acum. | H4: Realizado acum.
A5: Jan/26 | B5: =SUMIFS(Planejado!$H$5:$H$22,Planejado!$B$5:$B$22,"TI") | C5: =SUMIFS(Realizado!$H$5:$H$22,Realizado!$B$5:$B$22,"TI") | D5: =B5 | E5: =C5 | F5: =E5-D5 | G5: =SUM($D$5:D5) | H5: =SUM($E$5:E5)
A6: Fev/26 | B6: =SUMIFS(Planejado!$I$5:$I$22,Planejado!$B$5:$B$22,"TI") | C6: =SUMIFS(Realizado!$I$5:$I$22,Realizado!$B$5:$B$22,"TI") | D6: =B6 | E6: =C6 | F6: =E6-D6 | G6: =SUM($D$5:D6) | H6: =SUM($E$5:E6)
A7: Mar/26 | B7: =SUMIFS(Planejado!$J$5:$J$22,Planejado!$B$5:$B$22,"TI") | C7: =SUMIFS(Realizado!$J$5:$J$22,Realizado!$B$5:$B$22,"TI") | D7: =B7 | E7: =C7 | F7: =E7-D7 | G7: =SUM($D$5:D7) | H7: =SUM($E$5:E7)
A8: Abr/26 | B8: =SUMIFS(Planejado!$K$5:$K$22,Planejado!$B$5:$B$22,"TI") | C8: =SUMIFS(Realizado!$K$5:$K$22,Realizado!$B$5:$B$22,"TI") | D8: =B8 | E8: =C8 | F8: =E8-D8 | G8: =SUM($D$5:D8) | H8: =SUM($E$5:E8)
A9: Mai/26 | B9: =SUMIFS(Planejado!$L$5:$L$22,Planejado!$B$5:$B$22,"TI") | C9: =SUMIFS(Realizado!$L$5:$L$22,Realizado!$B$5:$B$22,"TI") | D9: =B9 | E9: =C9 | F9: =E9-D9 | G9: =SUM($D$5:D9) | H9: =SUM($E$5:E9)
A10: Jun/26 | B10: =SUMIFS(Planejado!$M$5:$M$22,Planejado!$B$5:$B$22,"TI") | C10: =SUMIFS(Realizado!$M$5:$M$22,Realizado!$B$5:$B$22,"TI") | D10: =B10 | E10: =C10 | F10: =E10-D10 | G10: =SUM($D$5:D10) | H10: =SUM($E$5:E10)
A11: Jul/26 | B11: =SUMIFS(Planejado!$N$5:$N$22,Planejado!$B$5:$B$22,"TI") | C11: =SUMIFS(Realizado!$N$5:$N$22,Realizado!$B$5:$B$22,"TI") | D11: =B11 | E11: =C11 | F11: =E11-D11 | G11: =SUM($D$5:D11) | H11: =SUM($E$5:E11)
A12: Ago/26 | B12: =SUMIFS(Planejado!$O$5:$O$22,Planejado!$B$5:$B$22,"TI") | C12: =SUMIFS(Realizado!$O$5:$O$22,Realizado!$B$5:$B$22,"TI") | D12: =B12 | E12: =C12 | F12: =E12-D12 | G12: =SUM($D$5:D12) | H12: =SUM($E$5:E12)
A13: Set/26 | B13: =SUMIFS(Planejado!$P$5:$P$22,Planejado!$B$5:$B$22,"TI") | C13: =SUMIFS(Realizado!$P$5:$P$22,Realizado!$B$5:$B$22,"TI") | D13: =B13 | E13: =C13 | F13: =E13-D13 | G13: =SUM($D$5:D13) | H13: =SUM($E$5:E13)
A14: Out/26 | B14: =SUMIFS(Planejado!$Q$5:$Q$22,Planejado!$B$5:$B$22,"TI") | C14: =SUMIFS(Realizado!$Q$5:$Q$22,Realizado!$B$5:$B$22,"TI") | D14: =B14 | E14: =C14 | F14: =E14-D14 | G14: =SUM($D$5:D14) | H14: =SUM($E$5:E14)
A15: Nov/26 | B15: =SUMIFS(Planejado!$R$5:$R$22,Planejado!$B$5:$B$22,"TI") | C15: =SUMIFS(Realizado!$R$5:$R$22,Realizado!$B$5:$B$22,"TI") | D15: =B15 | E15: =C15 | F15: =E15-D15 | G15: =SUM($D$5:D15) | H15: =SUM($E$5:E15)
A16: Dez/26 | B16: =SUMIFS(Planejado!$S$5:$S$22,Planejado!$B$5:$B$22,"TI") | C16: =SUMIFS(Realizado!$S$5:$S$22,Realizado!$B$5:$B$22,"TI") | D16: =B16 | E16: =C16 | F16: =E16-D16 | G16: =SUM($D$5:D16) | H16: =SUM($E$5:E16)
A17: TOTAL | B17: =SUM(B5:B16) | C17: =SUM(C5:C16) | D17: =SUM(D5:D16) | E17: =SUM(E5:E16) | F17: =SUM(F5:F16)

Sheet Por Plano de Contas
A1: RESUMO POR PLANO DE CONTAS
A2: Mesma referência de mês da aba Comparativo (B3). Serve para conversar com o financeiro na linguagem do plano de contas.
A4: Plano de Contas | B4: TI — Plan. | C4: TI — Real. | D4: Total Planejado acum. | E4: Total Realizado acum. | F4: Desvio (R$) | G4: Desvio (%) | H4: Orçado do ano
A5: Pessoal - CLT | B5: =SUMIFS(Comparativo!$I$6:$I$23,Comparativo!$E$6:$E$23,$A5,Comparativo!$B$6:$B$23,"TI") | C5: =SUMIFS(Comparativo!$J$6:$J$23,Comparativo!$E$6:$E$23,$A5,Comparativo!$B$6:$B$23,"TI") | D5: =B5 | E5: =C5 | F5: =E5-D5 | G5: =IFERROR(F5/D5,"") | H5: =SUMIFS(Planejado!$T$5:$T$22,Planejado!$G$5:$G$22,$A5)
A6: Pessoal - PJ | B6: =SUMIFS(Comparativo!$I$6:$I$23,Comparativo!$E$6:$E$23,$A6,Comparativo!$B$6:$B$23,"TI") | C6: =SUMIFS(Comparativo!$J$6:$J$23,Comparativo!$E$6:$E$23,$A6,Comparativo!$B$6:$B$23,"TI") | D6: =B6 | E6: =C6 | F6: =E6-D6 | G6: =IFERROR(F6/D6,"") | H6: =SUMIFS(Planejado!$T$5:$T$22,Planejado!$G$5:$G$22,$A6)
A7: Licenças de Softwares | B7: =SUMIFS(Comparativo!$I$6:$I$23,Comparativo!$E$6:$E$23,$A7,Comparativo!$B$6:$B$23,"TI") | C7: =SUMIFS(Comparativo!$J$6:$J$23,Comparativo!$E$6:$E$23,$A7,Comparativo!$B$6:$B$23,"TI") | D7: =B7 | E7: =C7 | F7: =E7-D7 | G7: =IFERROR(F7/D7,"") | H7: =SUMIFS(Planejado!$T$5:$T$22,Planejado!$G$5:$G$22,$A7)
A8: Custeio de Treinamento | B8: =SUMIFS(Comparativo!$I$6:$I$23,Comparativo!$E$6:$E$23,$A8,Comparativo!$B$6:$B$23,"TI") | C8: =SUMIFS(Comparativo!$J$6:$J$23,Comparativo!$E$6:$E$23,$A8,Comparativo!$B$6:$B$23,"TI") | D8: =B8 | E8: =C8 | F8: =E8-D8 | G8: =IFERROR(F8/D8,"") | H8: =SUMIFS(Planejado!$T$5:$T$22,Planejado!$G$5:$G$22,$A8)
A9: Prêmios | B9: =SUMIFS(Comparativo!$I$6:$I$23,Comparativo!$E$6:$E$23,$A9,Comparativo!$B$6:$B$23,"TI") | C9: =SUMIFS(Comparativo!$J$6:$J$23,Comparativo!$E$6:$E$23,$A9,Comparativo!$B$6:$B$23,"TI") | D9: =B9 | E9: =C9 | F9: =E9-D9 | G9: =IFERROR(F9/D9,"") | H9: =SUMIFS(Planejado!$T$5:$T$22,Planejado!$G$5:$G$22,$A9)
A10: Equipamentos Eletrônicos Diversos | B10: =SUMIFS(Comparativo!$I$6:$I$23,Comparativo!$E$6:$E$23,$A10,Comparativo!$B$6:$B$23,"TI") | C10: =SUMIFS(Comparativo!$J$6:$J$23,Comparativo!$E$6:$E$23,$A10,Comparativo!$B$6:$B$23,"TI") | D10: =B10 | E10: =C10 | F10: =E10-D10 | G10: =IFERROR(F10/D10,"") | H10: =SUMIFS(Planejado!$T$5:$T$22,Planejado!$G$5:$G$22,$A10)
A11: Móveis e Utensílios | B11: =SUMIFS(Comparativo!$I$6:$I$23,Comparativo!$E$6:$E$23,$A11,Comparativo!$B$6:$B$23,"TI") | C11: =SUMIFS(Comparativo!$J$6:$J$23,Comparativo!$E$6:$E$23,$A11,Comparativo!$B$6:$B$23,"TI") | D11: =B11 | E11: =C11 | F11: =E11-D11 | G11: =IFERROR(F11/D11,"") | H11: =SUMIFS(Planejado!$T$5:$T$22,Planejado!$G$5:$G$22,$A11)
A12: TOTAL | B12: =SUM(B5:B11) | C12: =SUM(C5:C11) | D12: =SUM(D5:D11) | E12: =SUM(E5:E11) | F12: =SUM(F5:F11) | G12: =IFERROR(F12/D12,"") | H12: =SUM(H5:H11)

Sheet Pendências
A1: PENDÊNCIAS E DECISÕES EM ABERTO
A2: Pontos que precisam ser fechados para o comparativo ficar confiável. Atualize a coluna Status conforme forem resolvidos.
A4: # | B4: Tema | C4: O que está em aberto | D4: Impacto no comparativo | E4: Responsável | F4: Status
A5: B | B5: Vinicius — custo total A LANÇAR | C5: Mesmo caso da Geovanna. O planejado é R$ 5.416,525/mês (custo total). Brutos confirmados: R$ 2.570,52 até jul/26 e R$ 3.070,52 a partir de 05/08/26 — o aumento é absorvido pela folga do envelope, que já previa reajuste, então o orçado não muda. O realizado está em branco. | D5: A folga do orçado NÃO é economia estrutural. Com o bruto de agosto, sobram R$ 2.346,01 para encargos, o que equivale a 76% sobre o bruto — dentro da faixa normal (67% a 80%), então pode sobrar ou estourar. Só o custo total real vai dizer. | E5: Cristiane + RH | F5: A LANÇAR
A6: F | B6: Jonathan — economia de R$ 53.803 até julho | C6: Orçado R$ 10.000/mês desde jan/26, com a contratação segurada até abr/26, quando ele passou a atuar como consultor fixo, 3 dias por semana. Realizado de R$ 16.196,99 em jan–jul (pagamentos de mai, jun e jul) contra R$ 70.000 orçados. O vínculo anterior, de serviços esporádicos prestados de fora, foi separado na linha TI-E04. | D6: É de longe a maior economia das duas áreas: R$ 53.803,01 em sete meses, e decorre de decisão de gestão, não de erro de orçamento. Vale destacar na apresentação. A CONFERIR: mai e jun saíram abaixo de R$ 6.300 (R$ 3.723,62 e R$ 6.173,37) — verificar se foi proporcional aos dias trabalhados no início do contrato. | E6: Cristiane | F6: CONFERIR
A7: Z | B7: Serviços esporádicos do Monitor Remoto — fora do orçamento | C7: Antes de entrar como consultor fixo, o mesmo prestador atendia de fora, em serviços esporádicos. Consta um pagamento de R$ 4.311,56 em 19/01/26 (NFS.70), provavelmente referente a dez/25 pelo regime de caixa. Esse vínculo não estava na ficha de orçamento e foi encerrado em abr/26. | D7: Linha TI-E04 criada com planejado zero, então o valor aparece como 'Não orçado'. Como o vínculo acabou, não haverá novos lançamentos — a linha existe para o histórico não se misturar com a consultoria fixa. Confirmar se houve pagamento esporádico em fev e mar que não caiu no centro de custo do TI. | E7: Cristiane | F7: CONFERIR
A8: G | B8: Elias Benedito — sem custo até jul, renegociado para set | C8: Orçado R$ 1.065/mês, realizado R$ 0 de jan a jul — contrato ativo, mas sem acionamento no período (confirmado pela gestora). O pagamento passa a ocorrer agora, e a partir de set/26 o valor foi renegociado de R$ 1.065 para R$ 603,30. | D8: Duas economias na mesma linha: R$ 7.455 pelos sete meses sem acionamento, e R$ 461,70/mês (43%) a partir de set pela renegociação — R$ 1.846,80 no ano. O planejado já reflete o valor novo de set a dez. | E8: Cristiane | F8: RESOLVIDO
A9: H | B9: Planejado de jan a abr — conferido | C9: O 1º quadrimestre foi preenchido replicando os valores mensais conhecidos, porque a ficha original só trazia o grid de mai a dez. Exceções tratadas: Jonathan começa em abr, Thamar a R$ 5.000 (pré-reajuste), Vinicius com bruto de R$ 2.570,52 e Adapta a R$ 1.300 (valor até jun). | D9: Conferido e validado pela gestora: os valores replicados estão corretos, nenhum ajuste necessário. | E9: Cristiane | F9: APLICADO
A10: I | B10: Realizado de ago a dez — a lançar no decorrer do ano | C10: Jan a jul estão lançados. Ago a dez ficam em branco e serão preenchidos conforme os meses fecharem, com a extração do SIENGE. | D10: Enquanto isso, o mês de referência do Comparativo deve ficar no último mês fechado (hoje Jul/26) — assim o acumulado compara períodos iguais dos dois lados. | E10: Cristiane | F10: APLICADO
A11: M | B11: Despesas fora do orçamento identificadas no extrato | C11: O extrato do financeiro traz gastos relevantes sem linha na ficha. Jurídico: Carneiro Rabelo (R$ 107.742) e Cristiane Carneiro Rabelo (R$ 94.825), somando R$ 202.567 em sete meses; mais Tribunal de Justiça (R$ 49.244), Michele de Oliveira (R$ 23.572) e ONR (R$ 22.576). TI: um bloco de telefonia e infraestrutura de cerca de R$ 15.700 (Claro, TIM, Telefônica, Locaweb, Web Mobile, Sabha, Intelbras, VC1, Alfama). O 'J H Alves — Monitor Remoto' NÃO entra nesta lista: é o Jonathan, que já tem linha no orçamento (TI-E03). | D11: Só os dois primeiros credores do Jurídico superam o orçamento anual inteiro do departamento. ATENÇÃO: parte desses valores pode ser repasse ou custa reembolsável pelo cliente, e não custo da área — foi o caso da Dra. Michele (ver item P). Separar o que é custo antes de decidir. Para os que entrarem no centro de custo, criar linha no orçamento, senão aparecerão como 'Não orçado' e distorcerão o comparativo. | E11: Cristiane + Diretoria | F11: PAUTA REUNIÃO
A12: J | B12: Despesas do TI — A LANÇAR | C12: As 9 linhas de despesas do TI (peças, backup, Adapta, antivírus, Office, sala de reunião, cursos, app de gravação e bonificação) não têm lançamento em nenhum mês. | D12: São R$ 89.040 orçados no ano, 35% do orçamento do TI. Sem lançamento, o departamento aparece com desvio negativo que é ausência de dado. | E12: Cristiane | F12: A LANÇAR
A13: 1 | B13: Base de meses do TI — Jonathan corrigido para 12 meses | C13: A ficha trazia os totais do TI digitados à mão: Vinicius e Elias em 12 meses (R$ 64.998,30 e R$ 12.780,00, ambos confirmados) e Jonathan em 9 meses (R$ 90.000). A gestora confirmou que o orçamento dele valia desde jan/26, ou seja, 12 meses — os R$ 90.000 da ficha não refletiam o orçamento aprovado. | D13: Equipe de TI passa de R$ 167.778,30 para R$ 197.778,30 (+R$ 30.000). Os R$ 167.778,30 da ficha continuam batendo com Vinicius e Elias, mas a linha do Jonathan estava subdimensionada em 3 meses. | E13: Cristiane | F13: RESOLVIDO
A14: 2 | B14: Origem do valor realizado — DEFINIDA: SIENGE | C14: Será aberto um centro de custo próprio no SIENGE e todos os valores do realizado serão extraídos de lá. Nada será lançado manualmente. O extrato das abas 'Contas Pagas' já vem nesse formato. | D14: O realizado passa a bater com a contabilidade por construção, que era o risco principal. Duas coisas a encaminhar: (1) o de-para entre credor do SIENGE e linha do orçamento — a coluna 'Já está no orçamento?' da aba de resumo é o rascunho dele; (2) definir se a extração sai por regime de caixa ou de competência, ver item 7. | E14: Cristiane + Financeiro | F14: RESOLVIDO
A15: Q | B15: Adapta lançado no centro de custo errado — RECLASSIFICAR | C15: Os pagamentos do Adapta (ADAPTA EDUCACAO LTDA, contrato 4134643529) estão no centro de custo Jurídico no SIENGE: R$ 575,00/mês de jan a mai e R$ 476,00 em jun, todos com vencimento dia 15. Total de R$ 3.351,00 em seis meses. Não é despesa do Jurídico — é ferramenta de IA, de uso transversal. | D15: DECIDIDO: solicitar a reclassificação contábil ao financeiro agora, sem esperar a abertura do centro de custo novo. Enquanto não for corrigido, o Jurídico carrega R$ 3.351 que não são dele e o TI aparece sem um gasto que é seu — as duas áreas ficam com o comparativo errado ao mesmo tempo. O que pedir ao financeiro: reclassificar os seis lançamentos do contrato 4134643529 (jan a jun/26) do centro de custo Jurídico para o de TI, e ajustar a classificação dos próximos para não repetir. Depois de reclassificado, aplicar o rateio do item L, já que é ferramenta de uso transversal. Quando o centro de custo novo abrir, conferir se a classificação nasceu certa. | E15: Cristiane + Financeiro | F15: SOLICITADA
... A28: 7 | B28: Competência x caixa — DECIDIDO: COMPETÊNCIA | C28: Todos os PJs prestam no mês e recebem no seguinte — Miguel, Thamar e Dra. Michele no Jurídico; Elias e Jonathan no TI. O realizado foi convertido para COMPETÊNCIA: os valores dos PJs foram deslocados um mês para trás em relação à data de pagamento. O que foi pago em jan/26 era serviço de dez/25 e saiu do exercício. | D28: Três efeitos. (1) O último mês completo passa a ser JUNHO, não julho: o serviço de jul só fecha quando sair o pagamento de ago — o mês de referência do Comparativo foi ajustado. (2) A conversão validou a entrada do Jonathan: por competência, o primeiro mês de serviço dele cai em abr, exatamente como informado. (3) O Monitor Remoto zerou no exercício — aquele pagamento de jan era serviço de dez/25. A CONFERIR: os CLT (Geovanna e Vinicius) NÃO foram deslocados. Se a folha for paga no mês seguinte, como é usual, eles também precisam deslocar. E na Thamar, confirmar se o aumento valeu para o serviço de mar ou de abr. Ao configurar a extração no SIENGE, travar o regime de competência e manter — trocar no meio do ano mistura critérios no histórico. | E28: Cristiane + Financeiro | F28: APLICADO

Sheet Como usar
A1: COMO USAR ESTA PLANILHA
A2: Rotina mensal de fechamento em 5 passos.
A4: ROTINA MENSAL
A5: 1 | B5: Extraia do SIENGE o relatório do centro de custo do departamento, no mês que fechou. A fonte do realizado é o SIENGE — nada é digitado de cabeça.
A6: 2 | B6: Lance na aba REALIZADO, nas células amarelas, o valor de cada linha do orçamento. Item sem gasto no mês: digite 0 — deixar em branco significa 'ainda não lancei'. Use a coluna 'Fonte do dado' para registrar de qual relatório o número saiu, com a data da extração.
A7: 3 | B7: Vá na aba COMPARATIVO e selecione o mês em B3. Todas as demais abas acompanham essa escolha.
A8: 4 | B8: Confira o PAINEL: ele mostra o desvio por departamento e os 5 maiores estouros do acumulado. É a tela para levar à diretoria.
A9: 5 | B9: Atualize a aba PENDÊNCIAS conforme as decisões forem sendo tomadas.
A11: PADRÃO DE DESCRIÇÃO
A12: Rubricas genéricas | B12: Em linhas que agrupam itens variados (peças de manutenção, equipamentos diversos), detalhe o item na descrição do lançamento no SIENGE, sempre no mesmo padrão: 'Peças – mouse', 'Peças – tela'. O orçamento fica numa linha só e o detalhe sai por filtro quando precisar.
A14: COMO LER OS NÚMEROS
A15: Desvio positivo (vermelho) | B15: Gastou ACIMA do orçado.
A16: Desvio negativo (verde) | B16: Gastou ABAIXO do orçado — economia ou despesa ainda não realizada.
A17: Planejado acum. | B17: Soma de maio até o mês selecionado.
A18: % Executado | B18: Realizado acumulado ÷ Planejado acumulado. Perto de 100% = no ritmo.
A19: Sem lançamento | B19: Nada foi lançado no realizado ainda — não confunda com economia.
A21: REGRAS DA PLANILHA
A22: Não altere | B22: As colunas de identificação da aba Realizado (A a G) são fórmulas que espelham a aba Planejado. Alterar quebra o comparativo.
A23: Nova linha de orçamento | B23: Insira na aba Planejado e replique a mesma linha na aba Realizado e na aba Comparativo, mantendo o mesmo ID.
A24: Revisão de orçamento | B24: Se a diretoria aprovar um valor novo, altere na aba Planejado e registre o motivo na aba Pendências.

Sheet Papéis e Responsabilidades
A1: PAPÉIS E RESPONSABILIDADES — equipe de TI
A2: Quem faz o quê no acompanhamento orçamentário e na operação. O critério é custo por hora: tarefa recorrente vai para quem custa menos, e a capacidade cara fica reservada para o que só ela resolve.
A4: Pessoa | B4: Função | C4: Vínculo | D4: Capacidade | E4: Custo/hora
A5: Cristiane Rabelo | B5: Gestora de TI e Jurídico | C5: — | D5: —
A6: Vinicius Di Franco | B6: Analista Administrativo | C6: CLT | D6: 173 h/mês (5x8h) | E6: 31.25
A7: Jonathan (J H Alves) | B7: Consultor / Desenvolvedor | C7: PJ | D7: 104 h/mês (3x8h) | E7: 60.58
A8: Elias Benedito | B8: Suporte Técnico Terceirizado | C8: PJ | D8: Sob demanda
A10: CRISTIANE — gestora de TI e Jurídico
A11: ESCOPO | B11: Responde pelas duas áreas: TI (R$ 284.971,50 orçados em 2026) e Jurídico (R$ 324.730,42), num total de R$ 609.701,92. Equipe direta de sete pessoas entre CLT e PJ.
A12: — ORÇAMENTO —
A13: Montar e revisar o orçamento | B13: Definir as linhas do ano, os valores e a base de meses de cada contrato. Revisar quando houver reajuste, entrada ou saída — como o aumento da Thamar, o do Vinicius e a inclusão da Dra. Michele.
A14: Aprovar o que entra e sai | B14: Nenhuma linha nova ou cancelamento sem passar por ela. Exemplos do período: cancelamento do Astrea, criação das linhas de IA, entrada do AnyDesk, decisão sobre a sala de reunião.
A15: Validar o fechamento mensal | B15: Conferir o que o analista lançou antes de o número virar informação oficial. Olhar a coluna 'Linhas lançadas' do Painel: desvio negativo em linha não lançada é ausência de dado, não economia.
A16: Responder pelo desvio | B16: Explicar cada estouro e cada economia — o que foi decisão de gestão, o que foi erro de origem do orçamento e o que é só falta de lançamento.
A17: — CONTRATOS E FORNECEDORES —
A18: Negociar valor e condições | B18: É o que gerou as economias do ano: Jonathan de R$ 10.000 para R$ 6.300 e Elias de R$ 1.065 para R$ 603,30, 43% de redução. Só a negociação responde por boa parte dos R$ 56.946 economizados no TI.
A19: Decidir contratar, manter ou cancelar | B19: Avaliar necessidade real antes de assinar e cortar o que não entrega. No período: Jusfy cancelado antes de iniciar, Astrea em cancelamento, contratação do Jonathan segurada por três meses.
A20: Controlar prazos de renovação | B20: Contratos anuais renovam sozinhos. O Astrea cobra em cartão e o ciclo vira em 01/11 — se o cancelamento não estiver confirmado até lá, entra anuidade de cerca de R$ 7.400 sem previsão orçamentária.
A21: — PESSOAS —
A22: Dimensionar a equipe | B22: Definir quem é CLT, quem é PJ, quantas horas e com que escopo. Decidir quando segurar uma contratação, como fez de jan a mar com o consultor.
A23: Alocar o trabalho por custo | B23: Manter a rotina com o analista e a capacidade cara reservada para o que só ela resolve. A hora do consultor custa o dobro e são só 104 por mês.
A24: Reajustes e bonificações | B24: Aprovar aumentos e decidir sobre as bonificações previstas em ago e dez, que somam R$ 29.160,60 nas duas áreas.
A25: — POLÍTICAS E GOVERNANÇA —
A26: Definir regras de uso | B26: Troca 1x1 de equipamento, estoque reserva para empréstimo, quem pode gerar chave de API, quem tem licença de IA e sob qual login.
A27: Rateio e centro de custo | B27: Definir com a controladoria o que é do TI e o que é corporativo: oito linhas de uso transversal estão marcadas como RATEIO A DEFINIR, e o Adapta está classificado na área errada.
A28: Zelar pelo sigilo | B28: Num escritório de advocacia, licença de IA compartilhada expõe o histórico de um cliente a quem não atua no caso. É risco de sigilo profissional, não só de custo.
A29: — RELACIONAMENTO —
A30: Diretoria | B30: Apresentar o Painel, defender os números e levar as pautas em aberto. Hoje são seis: sala de reunião, meta das IAs, notebooks, despesas fora do orçamento, reclassificação do Adapta e erro de origem do Astrea.
A31: Financeiro e controladoria | B31: Abertura do centro de custo no SIENGE, escolha do regime (competência ou caixa), reclassificações e separação entre custo e repasse.
A32: RH e Administrativo | B32: Custo total dos CLT para o comparativo, e o que sai do TI por não ser dele — papelaria e treinamento corporativo.
A33: Outras áreas | B33: Avisar antes do estouro quando uma solicitação de equipamento passar do saldo da rubrica delas.
A35: VINICIUS — suporte, rotina e apoio ao desenvolvimento
A36: Suporte ao usuário | B36: Atendimento do dia a dia às áreas: equipamento, acesso, software.
A37: Fechamento mensal do orçamento | B37: Extrair o relatório do centro de custo no SIENGE e lançar o realizado na aba Realizado, preenchendo a coluna Fonte do dado com a data da extração. Item sem gasto no mês recebe 0, não fica em branco.
A38: Controle de equipamentos | B38: Registrar solicitações e empréstimos na aba própria, cobrar a devolução do item quebrado na troca 1x1 e controlar o estoque reserva.
A39: Saldo por área | B39: Acompanhar quanto resta na rubrica de cada área e avisar ANTES de comprar quando a solicitação for levar ao estouro.
A40: Conferência de faturas | B40: Bater o valor cobrado contra o contrato. Foi assim que apareceram o Jusbrasil 30% acima e o Astrea a 5x o orçado.
A41: Padrão de descrição no SIENGE | B41: Em rubricas genéricas, detalhar o item na descrição do lançamento ('Peças – mouse', 'Peças – tela'), para a análise sair por filtro.
A42: Apoio operacional ao desenvolvimento | B42: Assumir as tarefas operacionais do que o Jonathan conduz. Cada hora que sai das mãos dele a R$ 31,25 libera uma hora de R$ 60,58 — é o que multiplica a capacidade limitada do consultor.
A44: JONATHAN — técnico e pontual, nunca rotina
...

Sheet Controle de Equipamentos
A1: CONTROLE DE EQUIPAMENTOS — solicitações, troca 1x1 e empréstimos
A2: Registro operacional do TI. O SIENGE mostra o que foi PAGO; esta aba mostra o que foi PEDIDO — é no intervalo entre os dois que dá para avisar a área antes de estourar o saldo.
A4: REGRAS
A5: Troca 1x1 | B5: Para receber um item novo, a pessoa entrega o que quebrou. O patrimônio devolvido é registrado na coluna própria.
A6: Empréstimo | B6: Quem está sem o equipamento sai com um reserva na hora, para não ficar parado. O reserva é COM FIO de propósito: mais barato e menos confortável que o definitivo, o que cria o incentivo para devolver e fechar a troca.
A7: Prazo: 7 dias | B7: O empréstimo vale por 7 dias corridos. Passou disso, o status vira 'Atrasado' e o TI cobra a devolução. A coluna 'Dias em posse' calcula sozinha a partir da data de saída.
A8: Sem devolução | B8: Se a pessoa não entrega o item antigo, a solicitação fica 'Pendente devolução' e não vira compra até ser resolvida.
A9: Aviso de saldo | B9: Antes de aprovar, conferir o saldo da rubrica da área solicitante. Se a compra for levar ao estouro, avisar a área ANTES de comprar (pendência R).
A11: SOLICITAÇÕES
A12: Data | B12: Área solicitante | C12: Solicitante | D12: Item | E12: Motivo | F12: Devolveu o antigo? | G12: Patrimônio devolvido | H12: Valor estimado | I12: Status | J12: Observações
A54: EMPRÉSTIMOS (equipamento reserva)
A55: Item emprestado | B55: Patrimônio | C55: Área | D55: Pessoa | E55: Saída em | F55: Previsão de devolução | G55: Devolvido em | H55: Status | I55: Dias em posse (limite: 7) | J55: Observações
I56: =IF(E56="","",IF(G56="",TODAY()-E56,G56-E56))
I57: =IF(E57="","",IF(G57="",TODAY()-E57,G57-E57))
I58: =IF(E58="","",IF(G58="",TODAY()-E58,G58-E58))
I59: =IF(E59="","",IF(G59="",TODAY()-E59,G59-E59))
I60: =IF(E60="","",IF(G60="",TODAY()-E60,G60-E60))
I61: =IF(E61="","",IF(G61="",TODAY()-E61,G61-E61))
I62: =IF(E62="","",IF(G62="",TODAY()-E62,G62-E62))
I63: =IF(E63="","",IF(G63="",TODAY()-E63,G63-E63))
I64: =IF(E64="","",IF(G64="",TODAY()-E64,G64-E64))
I65: =IF(E65="","",IF(G65="",TODAY()-E65,G65-E65))
I66: =IF(E66="","",IF(G66="",TODAY()-E66,G66-E66))
I67: =IF(E67="","",IF(G67="",TODAY()-E67,G67-E67))
... I80: =IF(E80="","",IF(G80="",TODAY()-E80,G80-E80))

Sheet Contas Pagas (resumo)
A1: CONTAS PAGAS — RESUMO POR CREDOR (TI)
A2: Extrato do financeiro, centro de custo "T.I". ABA DE APOIO: o centro de custo destes itens ainda não foi decidido, então nada aqui entra no Planejado, no Realizado nem no Painel. A coluna final aponta o que provavelmente já está no orçamento — confira e remova as duplicidades à mão.
A4: Credor | B4: Centro de Custo | C4: Nº lanç. | D4: Jan/26 | E4: Fev/26 | F4: Mar/26 | G4: Abr/26 | H4: Mai/26 | I4: Jun/26 | J4: Jul/26 | K4: TOTAL | L4: Já está no orçamento?
A5: J H ALVES - MONITOR REMOTO | B5: T.I | C5: 4 | D5: 4311.56 | H5: 3723.62 | I5: 6173.37 | J5: 6300 | K5: 20508.55 | L5: TI-E03 Jonathan (Monitor Remoto)
A6: VINICIUS DI FRANCO HEITOR | B6: T.I | C6: 23 | D6: 2670.84 | E6: 2986.04 | F6: 2778.04 | G6: 2751.04 | H6: 2719.04 | I6: 3633.16 | J6: 2461.04 | K6: 19999.2 | L6: TI-E01 Vinicius Di Franco
A7: OPENAI BRAZIL LIMITADA | B7: T.I | C7: 4 | E7: 234.46 | F7: 321.76 | G7: 5393.88 | K7: 5950.1 | L7: TI-D11 GPT
