Workbook

Sheet Painel
A1: PAINEL EXECUTIVO — Orçamento 2026 JURÍDICO E TI
A2: Acompanha o mês selecionado na aba Comparativo (célula B3). Desvio positivo = gastou acima do orçado. ATENÇÃO: confira a coluna 'Linhas lançadas' — desvio negativo em linha não lançada é ausência de dado, não economia.
A3: Mês de referência: | B3: =Comparativo!$B$3 | C3: (altere na aba Comparativo)
A4: ⚠ Geovanna: realizado em salário bruto; orçado em custo total — o desvio desta linha não é economia.
A5: Departamento | B5: Bloco | C5: Orçado do ano | D5: Planejado acum. | E5: Realizado acum. | F5: Desvio (R$) | G5: Desvio (%) | H5: % Executado do ano | I5: Linhas lançadas
A6: Jurídico | B6: Equipe | C6: =SUMIFS(Planejado!$T$5:$T$29,Planejado!$B$5:$B$29,"Jurídico",Planejado!$C$5:$C$29,"Equipe") | D6: =SUMIFS(Comparativo!$I$6:$I$30,Comparativo!$B$6:$B$30,"Jurídico",Comparativo!$C$6:$C$30,"Equipe") | E6: =SUMIFS(Comparativo!$J$6:$J$30,Comparativo!$B$6:$B$30,"Jurídico",Comparativo!$C$6:$C$30,"Equipe") | F6: =E6-D6 | G6: =IFERROR(F6/D6,"") | H6: =IFERROR(E6/C6,"") | I6: =COUNTIFS(Comparativo!$P$6:$P$30,">0",Comparativo!$B$6:$B$30,"Jurídico",Comparativo!$C$6:$C$30,"Equipe")&" de "&COUNTIFS(Comparativo!$A$6:$A$30,"?*",Comparativo!$B$6:$B$30,"Jurídico",Comparativo!$C$6:$C$30,"Equipe")
A7: Jurídico | B7: Despesas | C7: =SUMIFS(Planejado!$T$5:$T$29,Planejado!$B$5:$B$29,"Jurídico",Planejado!$C$5:$C$29,"Despesas") | D7: =SUMIFS(Comparativo!$I$6:$I$30,Comparativo!$B$6:$B$30,"Jurídico",Comparativo!$C$6:$C$30,"Despesas") | E7: =SUMIFS(Comparativo!$J$6:$J$30,Comparativo!$B$6:$B$30,"Jurídico",Comparativo!$C$6:$C$30,"Despesas") | F7: =E7-D7 | G7: =IFERROR(F7/D7,"") | H7: =IFERROR(E7/C7,"") | I7: =COUNTIFS(Comparativo!$P$6:$P$30,">0",Comparativo!$B$6:$B$30,"Jurídico",Comparativo!$C$6:$C$30,"Despesas")&" de "&COUNTIFS(Comparativo!$A$6:$A$30,"?*",Comparativo!$B$6:$B$30,"Jurídico",Comparativo!$C$6:$C$30,"Despesas")
A8: Jurídico | B8: Equipe + Despesas | C8: =SUMIFS(Planejado!$T$5:$T$29,Planejado!$B$5:$B$29,"Jurídico") | D8: =SUMIFS(Comparativo!$I$6:$I$30,Comparativo!$B$6:$B$30,"Jurídico") | E8: =SUMIFS(Comparativo!$J$6:$J$30,Comparativo!$B$6:$B$30,"Jurídico") | F8: =E8-D8 | G8: =IFERROR(F8/D8,"") | H8: =IFERROR(E8/C8,"") | I8: =COUNTIFS(Comparativo!$P$6:$P$30,">0",Comparativo!$B$6:$B$30,"Jurídico")&" de "&COUNTIFS(Comparativo!$A$6:$A$30,"?*",Comparativo!$B$6:$B$30,"Jurídico")
A9: TI | B9: Equipe | C9: =SUMIFS(Planejado!$T$5:$T$29,Planejado!$B$5:$B$29,"TI",Planejado!$C$5:$C$29,"Equipe") | D9: =SUMIFS(Comparativo!$I$6:$I$30,Comparativo!$B$6:$B$30,"TI",Comparativo!$C$6:$C$30,"Equipe") | E9: =SUMIFS(Comparativo!$J$6:$J$30,Comparativo!$B$6:$B$30,"TI",Comparativo!$C$6:$C$30,"Equipe") | F9: =E9-D9 | G9: =IFERROR(F9/D9,"") | H9: =IFERROR(E9/C9,"") | I9: =COUNTIFS(Comparativo!$P$6:$P$30,">0",Comparativo!$B$6:$B$30,"TI",Comparativo!$C$6:$C$30,"Equipe")&" de "&COUNTIFS(Comparativo!$A$6:$A$30,"?*",Comparativo!$B$6:$B$30,"TI",Comparativo!$C$6:$C$30,"Equipe")
A10: TI | B10: Despesas | C10: =SUMIFS(Planejado!$T$5:$T$29,Planejado!$B$5:$B$29,"TI",Planejado!$C$5:$C$29,"Despesas") | D10: =SUMIFS(Comparativo!$I$6:$I$30,Comparativo!$B$6:$B$30,"TI",Comparativo!$C$6:$C$30,"Despesas") | E10: =SUMIFS(Comparativo!$J$6:$J$30,Comparativo!$B$6:$B$30,"TI",Comparativo!$C$6:$C$30,"Despesas") | F10: =E10-D10 | G10: =IFERROR(F10/D10,"") | H10: =IFERROR(E10/C10,"") | I10: =COUNTIFS(Comparativo!$P$6:$P$30,">0",Comparativo!$B$6:$B$30,"TI",Comparativo!$C$6:$C$30,"Despesas")&" de "&COUNTIFS(Comparativo!$A$6:$A$30,"?*",Comparativo!$B$6:$B$30,"TI",Comparativo!$C$6:$C$30,"Despesas")
A11: TI | B11: Equipe + Despesas | C11: =SUMIFS(Planejado!$T$5:$T$29,Planejado!$B$5:$B$29,"TI") | D11: =SUMIFS(Comparativo!$I$6:$I$30,Comparativo!$B$6:$B$30,"TI") | E11: =SUMIFS(Comparativo!$J$6:$J$30,Comparativo!$B$6:$B$30,"TI") | F11: =E11-D11 | G11: =IFERROR(F11/D11,"") | H11: =IFERROR(E11/C11,"") | I11: =COUNTIFS(Comparativo!$P$6:$P$30,">0",Comparativo!$B$6:$B$30,"TI")&" de "&COUNTIFS(Comparativo!$A$6:$A$30,"?*",Comparativo!$B$6:$B$30,"TI")
A12: TOTAL GERAL | C12: =SUM(Planejado!$T$5:$T$29) | D12: =SUM(Comparativo!$I$6:$I$30) | E12: =SUM(Comparativo!$J$6:$J$30) | F12: =E12-D12 | G12: =IFERROR(F12/D12,"") | H12: =IFERROR(E12/C12,"") | I12: =COUNTIFS(Comparativo!$P$6:$P$30,">0")&" de "&COUNTA(Comparativo!$A$6:$A$30)
A15: ECONOMIA GERADA — acumulado de janeiro até o mês de referência
A16: Economia bruta | C16: =-SUMIF(Comparativo!$Q$6:$Q$30,"<0") | D16: Soma de tudo que ficou abaixo do orçado
A17: (−) Gastos acima do orçado | C17: =-SUMIF(Comparativo!$Q$6:$Q$30,">0") | D17: Estouros que consomem parte da economia
A18: =ECONOMIA LÍQUIDA | C18: =-SUM(Comparativo!$Q$6:$Q$30) | D18: O número defensável: só linhas comparáveis
A19: Projeção para o ano | C19: =IFERROR(-SUM(Comparativo!$Q$6:$Q$30)/Comparativo!$D$3*12,"") | D19: Extrapolação linear, se o padrão dos meses fechados se mantiver
A20: % sobre o orçado do período | C20: =IFERROR(-SUM(Comparativo!$Q$6:$Q$30)/SUM(Comparativo!$S$6:$S$30),"") | D20: Economia líquida ÷ planejado das linhas que entram na conta
A21: Fora desta conta: linhas sem nenhum lançamento; Geovanna (base diferente). Só entra o que foi efetivamente lançado e é comparável.
A23: DE ONDE VEIO A ECONOMIA (top 5)
A24: # | B24: Item | C24: Departamento | D24: Planejado acum. | E24: Realizado acum. | F24: Economia (R$) | G24: % da linha
A25: 1 | B25: =IFERROR(INDEX(Comparativo!$D$6:$D$30,MATCH(LARGE(Comparativo!$R$6:$R$30,A25),Comparativo!$R$6:$R$30,0)),"") | C25: =IFERROR(INDEX(Comparativo!$B$6:$B$30,MATCH(LARGE(Comparativo!$R$6:$R$30,A25),Comparativo!$R$6:$R$30,0)),"") | D25: =IFERROR(INDEX(Comparativo!$I$6:$I$30,MATCH(LARGE(Comparativo!$R$6:$R$30,A25),Comparativo!$R$6:$R$30,0)),"") | E25: =IFERROR(INDEX(Comparativo!$J$6:$J$30,MATCH(LARGE(Comparativo!$R$6:$R$30,A25),Comparativo!$R$6:$R$30,0)),"") | F25: =IFERROR(-IFERROR(INDEX(Comparativo!$K$6:$K$30,MATCH(LARGE(Comparativo!$R$6:$R$30,A25),Comparativo!$R$6:$R$30,0)),""),"") | G25: =IFERROR(F25/D25,"")
A26: 2 | B26: =IFERROR(INDEX(Comparativo!$D$6:$D$30,MATCH(LARGE(Comparativo!$R$6:$R$30,A26),Comparativo!$R$6:$R$30,0)),"") | C26: =IFERROR(INDEX(Comparativo!$B$6:$B$30,MATCH(LARGE(Comparativo!$R$6:$R$30,A26),Comparativo!$R$6:$R$30,0)),"") | D26: =IFERROR(INDEX(Comparativo!$I$6:$I$30,MATCH(LARGE(Comparativo!$R$6:$R$30,A26),Comparativo!$R$6:$R$30,0)),"") | E26: =IFERROR(INDEX(Comparativo!$J$6:$J$30,MATCH(LARGE(Comparativo!$R$6:$R$30,A26),Comparativo!$R$6:$R$30,0)),"") | F26: =IFERROR(-IFERROR(INDEX(Comparativo!$K$6:$K$30,MATCH(LARGE(Comparativo!$R$6:$R$30,A26),Comparativo!$R$6:$R$30,0)),""),"") | G26: =IFERROR(F26/D26,"")
A27: 3 | B27: =IFERROR(INDEX(Comparativo!$D$6:$D$30,MATCH(LARGE(Comparativo!$R$6:$R$30,A27),Comparativo!$R$6:$R$30,0)),"") | C27: =IFERROR(INDEX(Comparativo!$B$6:$B$30,MATCH(LARGE(Comparativo!$R$6:$R$30,A27),Comparativo!$R$6:$R$30,0)),"") | D27: =IFERROR(INDEX(Comparativo!$I$6:$I$30,MATCH(LARGE(Comparativo!$R$6:$R$30,A27),Comparativo!$R$6:$R$30,0)),"") | E27: =IFERROR(INDEX(Comparativo!$J$6:$J$30,MATCH(LARGE(Comparativo!$R$6:$R$30,A27),Comparativo!$R$6:$R$30,0)),"") | F27: =IFERROR(-IFERROR(INDEX(Comparativo!$K$6:$K$30,MATCH(LARGE(Comparativo!$R$6:$R$30,A27),Comparativo!$R$6:$R$30,0)),""),"") | G27: =IFERROR(F27/D27,"")
A28: 4 | B28: =IFERROR(INDEX(Comparativo!$D$6:$D$30,MATCH(LARGE(Comparativo!$R$6:$R$30,A28),Comparativo!$R$6:$R$30,0)),"") | C28: =IFERROR(INDEX(Comparativo!$B$6:$B$30,MATCH(LARGE(Comparativo!$R$6:$R$30,A28),Comparativo!$R$6:$R$30,0)),"") | D28: =IFERROR(INDEX(Comparativo!$I$6:$I$30,MATCH(LARGE(Comparativo!$R$6:$R$30,A28),Comparativo!$R$6:$R$30,0)),"") | E28: =IFERROR(INDEX(Comparativo!$J$6:$J$30,MATCH(LARGE(Comparativo!$R$6:$R$30,A28),Comparativo!$R$6:$R$30,0)),"") | F28: =IFERROR(-IFERROR(INDEX(Comparativo!$K$6:$K$30,MATCH(LARGE(Comparativo!$R$6:$R$30,A28),Comparativo!$R$6:$R$30,0)),""),"") | G28: =IFERROR(F28/D28,"")
A29: 5 | B29: =IFERROR(INDEX(Comparativo!$D$6:$D$30,MATCH(LARGE(Comparativo!$R$6:$R$30,A29),Comparativo!$R$6:$R$30,0)),"") | C29: =IFERROR(INDEX(Comparativo!$B$6:$B$30,MATCH(LARGE(Comparativo!$R$6:$R$30,A29),Comparativo!$R$6:$R$30,0)),"") | D29: =IFERROR(INDEX(Comparativo!$I$6:$I$30,MATCH(LARGE(Comparativo!$R$6:$R$30,A29),Comparativo!$R$6:$R$30,0)),"") | E29: =IFERROR(INDEX(Comparativo!$J$6:$J$30,MATCH(LARGE(Comparativo!$R$6:$R$30,A29),Comparativo!$R$6:$R$30,0)),"") | F29: =IFERROR(-IFERROR(INDEX(Comparativo!$K$6:$K$30,MATCH(LARGE(Comparativo!$R$6:$R$30,A29),Comparativo!$R$6:$R$30,0)),""),"") | G29: =IFERROR(F29/D29,"")
A32: MAIORES DESVIOS DO ACUMULADO (top 5 acima do orçado)
A33: # | B33: Item | C33: Departamento | D33: Planejado acum. | E33: Realizado acum. | F33: Desvio (R$) | G33: Desvio (%)
A34: 1 | B34: =IFERROR(INDEX(Comparativo!$D$6:$D$30,MATCH(LARGE(Comparativo!$O$6:$O$30,A34),Comparativo!$O$6:$O$30,0)),"") | C34: =IFERROR(INDEX(Comparativo!$B$6:$B$30,MATCH(LARGE(Comparativo!$O$6:$O$30,A34),Comparativo!$O$6:$O$30,0)),"") | D34: =IFERROR(INDEX(Comparativo!$I$6:$I$30,MATCH(LARGE(Comparativo!$O$6:$O$30,A34),Comparativo!$O$6:$O$30,0)),"") | E34: =IFERROR(INDEX(Comparativo!$J$6:$J$30,MATCH(LARGE(Comparativo!$O$6:$O$30,A34),Comparativo!$O$6:$O$30,0)),"") | F34: =IFERROR(INDEX(Comparativo!$K$6:$K$30,MATCH(LARGE(Comparativo!$O$6:$O$30,A34),Comparativo!$O$6:$O$30,0)),"") | G34: =IFERROR(F34/D34,"")
A35: 2 | B35: =IFERROR(INDEX(Comparativo!$D$6:$D$30,MATCH(LARGE(Comparativo!$O$6:$O$30,A35),Comparativo!$O$6:$O$30,0)),"") | C35: =IFERROR(INDEX(Comparativo!$B$6:$B$30,MATCH(LARGE(Comparativo!$O$6:$O$30,A35),Comparativo!$O$6:$O$30,0)),"") | D35: =IFERROR(INDEX(Comparativo!$I$6:$I$30,MATCH(LARGE(Comparativo!$O$6:$O$30,A35),Comparativo!$O$6:$O$30,0)),"") | E35: =IFERROR(INDEX(Comparativo!$J$6:$J$30,MATCH(LARGE(Comparativo!$O$6:$O$30,A35),Comparativo!$O$6:$O$30,0)),"") | F35: =IFERROR(INDEX(Comparativo!$K$6:$K$30,MATCH(LARGE(Comparativo!$O$6:$O$30,A35),Comparativo!$O$6:$O$30,0)),"") | G35: =IFERROR(F35/D35,"")
A36: 3 | B36: =IFERROR(INDEX(Comparativo!$D$6:$D$30,MATCH(LARGE(Comparativo!$O$6:$O$30,A36),Comparativo!$O$6:$O$30,0)),"") | C36: =IFERROR(INDEX(Comparativo!$B$6:$B$30,MATCH(LARGE(Comparativo!$O$6:$O$30,A36),Comparativo!$O$6:$O$30,0)),"") | D36: =IFERROR(INDEX(Comparativo!$I$6:$I$30,MATCH(LARGE(Comparativo!$O$6:$O$30,A36),Comparativo!$O$6:$O$30,0)),"") | E36: =IFERROR(INDEX(Comparativo!$J$6:$J$30,MATCH(LARGE(Comparativo!$O$6:$O$30,A36),Comparativo!$O$6:$O$30,0)),"") | F36: =IFERROR(INDEX(Comparativo!$K$6:$K$30,MATCH(LARGE(Comparativo!$O$6:$O$30,A36),Comparativo!$O$6:$O$30,0)),"") | G36: =IFERROR(F36/D36,"")
A37: 4 | B37: =IFERROR(INDEX(Comparativo!$D$6:$D$30,MATCH(LARGE(Comparativo!$O$6:$O$30,A37),Comparativo!$O$6:$O$30,0)),"") | C37: =IFERROR(INDEX(Comparativo!$B$6:$B$30,MATCH(LARGE(Comparativo!$O$6:$O$30,A37),Comparativo!$O$6:$O$30,0)),"") | D37: =IFERROR(INDEX(Comparativo!$I$6:$I$30,MATCH(LARGE(Comparativo!$O$6:$O$30,A37),Comparativo!$O$6:$O$30,0)),"") | E37: =IFERROR(INDEX(Comparativo!$J$6:$J$30,MATCH(LARGE(Comparativo!$O$6:$O$30,A37),Comparativo!$O$6:$O$30,0)),"") | F37: =IFERROR(INDEX(Comparativo!$K$6:$K$30,MATCH(LARGE(Comparativo!$O$6:$O$30,A37),Comparativo!$O$6:$O$30,0)),"") | G37: =IFERROR(F37/D37,"")
A38: 5 | B38: =IFERROR(INDEX(Comparativo!$D$6:$D$30,MATCH(LARGE(Comparativo!$O$6:$O$30,A38),Comparativo!$O$6:$O$30,0)),"") | C38: =IFERROR(INDEX(Comparativo!$B$6:$B$30,MATCH(LARGE(Comparativo!$O$6:$O$30,A38),Comparativo!$O$6:$O$30,0)),"") | D38: =IFERROR(INDEX(Comparativo!$I$6:$I$30,MATCH(LARGE(Comparativo!$O$6:$O$30,A38),Comparativo!$O$6:$O$30,0)),"") | E38: =IFERROR(INDEX(Comparativo!$J$6:$J$30,MATCH(LARGE(Comparativo!$O$6:$O$30,A38),Comparativo!$O$6:$O$30,0)),"") | F38: =IFERROR(INDEX(Comparativo!$K$6:$K$30,MATCH(LARGE(Comparativo!$O$6:$O$30,A38),Comparativo!$O$6:$O$30,0)),"") | G38: =IFERROR(F38/D38,"")

Sheet Comparativo
A1: PLANEJADO x REALIZADO — linha a linha
A2: Escolha o mês de referência em B3. As colunas 'no mês' mostram só aquele mês; as colunas 'acumulado' somam de maio até o mês escolhido. Desvio positivo = gastou ACIMA do orçado.
A3: Mês de referência: | B3: Jul/26 | C3: Mês nº: | D3: =MATCH($B$3,Planejado!$H$4:$S$4,0)
A5: ID | B5: Departamento | C5: Bloco | D5: Descrição | E5: Plano de Contas | F5: Planejado no mês | G5: Realizado no mês | H5: Desvio no mês (R$) | I5: Planejado acum. | J5: Realizado acum. | K5: Desvio acum. (R$) | L5: Desvio acum. (%) | M5: % Executado | N5: Situação | O5: (aux ranking) | P5: (aux meses lançados) | Q5: (aux desvio comparável) | R5: (aux ranking economia) | S5: (aux planejado comparável)
A6: =Planejado!A5 | B6: =Planejado!B5 | C6: =Planejado!C5 | D6: =Planejado!D5 | E6: =Planejado!G5 | F6: =INDEX(Planejado!$H5:$S5,$D$3) | G6: =INDEX(Realizado!$H5:$S5,$D$3) | H6: =G6-F6 | I6: =SUMPRODUCT((COLUMN(Planejado!$H$4:$S$4)-COLUMN(Planejado!$H$4)+1<=$D$3)*Planejado!$H5:$S5) | J6: =SUMPRODUCT((COLUMN(Realizado!$H$4:$S$4)-COLUMN(Realizado!$H$4)+1<=$D$3)*Realizado!$H5:$S5) | K6: =J6-I6 | L6: =IFERROR(K6/I6,"") | M6: =IFERROR(J6/I6,"") | N6: =IF(P6=0,"Sem lançamento",IF(AND(I6=0,J6=0),"—",IF(I6=0,"Não orçado",IF(K6>0.05*I6,"Acima do orçado",IF(K6<-0.05*I6,"Abaixo do orçado","Dentro do orçado"))))) | O6: =IF(K6>1,K6+ROW()/1000000,"") | P6: =SUMPRODUCT((COLUMN(Realizado!$H$4:$S$4)-COLUMN(Realizado!$H$4)+1<=$D$3)*(Realizado!$H5:$S5<>"")) | Q6: =IF(P6=0,"",K6) | R6: =IF(AND(Q6<>"",Q6<-1),-Q6+ROW()/1000000,"") | S6: =IF(Q6="","",I6)
A7: =Planejado!A6 | B7: =Planejado!B6 | C7: =Planejado!C6 | D7: =Planejado!D6 | E7: =Planejado!G6 | F7: =INDEX(Planejado!$H6:$S6,$D$3) | G7: =INDEX(Realizado!$H6:$S6,$D$3) | H7: =G7-F7 | I7: =SUMPRODUCT((COLUMN(Planejado!$H$4:$S$4)-COLUMN(Planejado!$H$4)+1<=$D$3)*Planejado!$H6:$S6) | J7: =SUMPRODUCT((COLUMN(Realizado!$H$4:$S$4)-COLUMN(Realizado!$H$4)+1<=$D$3)*Realizado!$H6:$S6) | K7: =J7-I7 | L7: =IFERROR(K7/I7,"") | M7: =IFERROR(J7/I7,"") | N7: ⚠ Base diferente | O7: =IF(K7>1,K7+ROW()/1000000,"") | P7: =SUMPRODUCT((COLUMN(Realizado!$H$4:$S$4)-COLUMN(Realizado!$H$4)+1<=$D$3)*(Realizado!$H6:$S6<>"")) | R7: =IF(AND(Q7<>"",Q7<-1),-Q7+ROW()/1000000,"") | S7: =IF(Q7="","",I7)
A8: =Planejado!A7 | B8: =Planejado!B7 | C8: =Planejado!C7 | D8: =Planejado!D7 | E8: =Planejado!G7 | F8: =INDEX(Planejado!$H7:$S7,$D$3) | G8: =INDEX(Realizado!$H7:$S7,$D$3) | H8: =G8-F8 | I8: =SUMPRODUCT((COLUMN(Planejado!$H$4:$S$4)-COLUMN(Planejado!$H$4)+1<=$D$3)*Planejado!$H7:$S7) | J8: =SUMPRODUCT((COLUMN(Realizado!$H$4:$S$4)-COLUMN(Realizado!$H$4)+1<=$D$3)*Realizado!$H7:$S7) | K8: =J8-I8 | L8: =IFERROR(K8/I8,"") | M8: =IFERROR(J8/I8,"") | N8: =IF(P8=0,"Sem lançamento",IF(AND(I8=0,J8=0),"—",IF(I8=0,"Não orçado",IF(K8>0.05*I8,"Acima do orçado",IF(K8<-0.05*I8,"Abaixo do orçado","Dentro do orçado"))))) | O8: =IF(K8>1,K8+ROW()/1000000,"") | P8: =SUMPRODUCT((COLUMN(Realizado!$H$4:$S$4)-COLUMN(Realizado!$H$4)+1<=$D$3)*(Realizado!$H7:$S7<>"")) | Q8: =IF(P8=0,"",K8) | R8: =IF(AND(Q8<>"",Q8<-1),-Q8+ROW()/1000000,"") | S8: =IF(Q8="","",I8)
A9: =Planejado!A8 | B9: =Planejado!B8 | C9: =Planejado!C8 | D9: =Planejado!D8 | E9: =Planejado!G8 | F9: =INDEX(Planejado!$H8:$S8,$D$3) | G9: =INDEX(Realizado!$H8:$S8,$D$3) | H9: =G9-F9 | I9: =SUMPRODUCT((COLUMN(Planejado!$H$4:$S$4)-COLUMN(Planejado!$H$4)+1<=$D$3)*Planejado!$H8:$S8) | J9: =SUMPRODUCT((COLUMN(Realizado!$H$4:$S$4)-COLUMN(Realizado!$H$4)+1<=$D$3)*Realizado!$H8:$S8) | K9: =J9-I9 | L9: =IFERROR(K9/I9,"") | M9: =IFERROR(J9/I9,"") | N9: =IF(P9=0,"Sem lançamento",IF(AND(I9=0,J9=0),"—",IF(I9=0,"Não orçado",IF(K9>0.05*I9,"Acima do orçado",IF(K9<-0.05*I9,"Abaixo do orçado","Dentro do orçado"))))) | O9: =IF(K9>1,K9+ROW()/1000000,"") | P9: =SUMPRODUCT((COLUMN(Realizado!$H$4:$S$4)-COLUMN(Realizado!$H$4)+1<=$D$3)*(Realizado!$H8:$S8<>"")) | Q9: =IF(P9=0,"",K9) | R9: =IF(AND(Q9<>"",Q9<-1),-Q9+ROW()/1000000,"") | S9: =IF(Q9="","",I9)
A10: =Planejado!A9 | B10: =Planejado!B9 | C10: =Planejado!C9 | D10: =Planejado!D9 | E10: =Planejado!G9 | F10: =INDEX(Planejado!$H9:$S9,$D$3) | G10: =INDEX(Realizado!$H9:$S9,$D$3) | H10: =G10-F10 | I10: =SUMPRODUCT((COLUMN(Planejado!$H$4:$S$4)-COLUMN(Planejado!$H$4)+1<=$D$3)*Planejado!$H9:$S9) | J10: =SUMPRODUCT((COLUMN(Realizado!$H$4:$S$4)-COLUMN(Realizado!$H$4)+1<=$D$3)*Realizado!$H9:$S9) | K10: =J10-I10 | L10: =IFERROR(K10/I10,"") | M10: =IFERROR(J10/I10,"") | N10: =IF(P10=0,"Sem lançamento",IF(AND(I10=0,J10=0),"—",IF(I10=0,"Não orçado",IF(K10>0.05*I10,"Acima do orçado",IF(K10<-0.05*I10,"Abaixo do orçado","Dentro do orçado"))))) | O10: =IF(K10>1,K10+ROW()/1000000,"") | P10: =SUMPRODUCT((COLUMN(Realizado!$H$4:$S$4)-COLUMN(Realizado!$H$4)+1<=$D$3)*(Realizado!$H9:$S9<>"")) | Q10: =IF(P10=0,"",K10) | R10: =IF(AND(Q10<>"",Q10<-1),-Q10+ROW()/1000000,"") | S10: =IF(Q10="","",I10)
A11: =Planejado!A10 | B11: =Planejado!B10 | C11: =Planejado!C10 | D11: =Planejado!D10 | E11: =Planejado!G10 | F11: =INDEX(Planejado!$H10:$S10,$D$3) | G11: =INDEX(Realizado!$H10:$S10,$D$3) | H11: =G11-F11 | I11: =SUMPRODUCT((COLUMN(Planejado!$H$4:$S$4)-COLUMN(Planejado!$H$4)+1<=$D$3)*Planejado!$H10:$S10) | J11: =SUMPRODUCT((COLUMN(Realizado!$H$4:$S$4)-COLUMN(Realizado!$H$4)+1<=$D$3)*Realizado!$H10:$S10) | K11: =J11-I11 | L11: =IFERROR(K11/I11,"") | M11: =IFERROR(J11/I11,"") | N11: =IF(P11=0,"Sem lançamento",IF(AND(I11=0,J11=0),"—",IF(I11=0,"Não orçado",IF(K11>0.05*I11,"Acima do orçado",IF(K11<-0.05*I11,"Abaixo do orçado","Dentro do orçado"))))) | O11: =IF(K11>1,K11+ROW()/1000000,"") | P11: =SUMPRODUCT((COLUMN(Realizado!$H$4:$S$4)-COLUMN(Realizado!$H$4)+1<=$D$3)*(Realizado!$H10:$S10<>"")) | Q11: =IF(P11=0,"",K11) | R11: =IF(AND(Q11<>"",Q11<-1),-Q11+ROW()/1000000,"") | S11: =IF(Q11="","",I11)
A12: =Planejado!A11 | B12: =Planejado!B11 | C12: =Planejado!C11 | D12: =Planejado!D11 | E12: =Planejado!G11 | F12: =INDEX(Planejado!$H11:$S11,$D$3) | G12: =INDEX(Realizado!$H11:$S11,$D$3) | H12: =G12-F12 | I12: =SUMPRODUCT((COLUMN(Planejado!$H$4:$S$4)-COLUMN(Planejado!$H$4)+1<=$D$3)*Planejado!$H11:$S11) | J12: =SUMPRODUCT((COLUMN(Realizado!$H$4:$S$4)-COLUMN(Realizado!$H$4)+1<=$D$3)*Realizado!$H11:$S11) | K12: =J12-I12 | L12: =IFERROR(K12/I12,"") | M12: =IFERROR(J12/I12,"") | N12: =IF(P12=0,"Sem lançamento",IF(AND(I12=0,J12=0),"—",IF(I12=0,"Não orçado",IF(K12>0.05*I12,"Acima do orçado",IF(K12<-0.05*I12,"Abaixo do orçado","Dentro do orçado"))))) | O12: =IF(K12>1,K12+ROW()/1000000,"") | P12: =SUMPRODUCT((COLUMN(Realizado!$H$4:$S$4)-COLUMN(Realizado!$H$4)+1<=$D$3)*(Realizado!$H11:$S11<>"")) | Q12: =IF(P12=0,"",K12) | R12: =IF(AND(Q12<>"",Q12<-1),-Q12+ROW()/1000000,"") | S12: =IF(Q12="","",I12)
A13: =Planejado!A12 | B13: =Planejado!B12 | C13: =Planejado!C12 | D13: =Planejado!D12 | E13: =Planejado!G12 | F13: =INDEX(Planejado!$H12:$S12,$D$3) | G13: =INDEX(Realizado!$H12:$S12,$D$3) | H13: =G13-F13 | I13: =SUMPRODUCT((COLUMN(Planejado!$H$4:$S$4)-COLUMN(Planejado!$H$4)+1<=$D$3)*Planejado!$H12:$S12) | J13: =SUMPRODUCT((COLUMN(Realizado!$H$4:$S$4)-COLUMN(Realizado!$H$4)+1<=$D$3)*Realizado!$H12:$S12) | K13: =J13-I13 | L13: =IFERROR(K13/I13,"") | M13: =IFERROR(J13/I13,"") | N13: =IF(P13=0,"Sem lançamento",IF(AND(I13=0,J13=0),"—",IF(I13=0,"Não orçado",IF(K13>0.05*I13,"Acima do orçado",IF(K13<-0.05*I13,"Abaixo do orçado","Dentro do orçado"))))) | O13: =IF(K13>1,K13+ROW()/1000000,"") | P13: =SUMPRODUCT((COLUMN(Realizado!$H$4:$S$4)-COLUMN(Realizado!$H$4)+1<=$D$3)*(Realizado!$H12:$S12<>"")) | Q13: =IF(P13=0,"",K13) | R13: =IF(AND(Q13<>"",Q13<-1),-Q13+ROW()/1000000,"") | S13: =IF(Q13="","",I13)
A14: =Planejado!A13 | B14: =Planejado!B13 | C14: =Planejado!C13 | D14: =Planejado!D13 | E14: =Planejado!G13 | F14: =INDEX(Planejado!$H13:$S13,$D$3) | G14: =INDEX(Realizado!$H13:$S13,$D$3) | H14: =G14-F14 | I14: =SUMPRODUCT((COLUMN(Planejado!$H$4:$S$4)-COLUMN(Planejado!$H$4)+1<=$D$3)*Planejado!$H13:$S13) | J14: =SUMPRODUCT((COLUMN(Realizado!$H$4:$S$4)-COLUMN(Realizado!$H$4)+1<=$D$3)*Realizado!$H13:$S13) | K14: =J14-I14 | L14: =IFERROR(K14/I14,"") | M14: =IFERROR(J14/I14,"") | N14: =IF(P14=0,"Sem lançamento",IF(AND(I14=0,J14=0),"—",IF(I14=0,"Não orçado",IF(K14>0.05*I14,"Acima do orçado",IF(K14<-0.05*I14,"Abaixo do orçado","Dentro do orçado"))))) | O14: =IF(K14>1,K14+ROW()/1000000,"") | P14: =SUMPRODUCT((COLUMN(Realizado!$H$4:$S$4)-COLUMN(Realizado!$H$4)+1<=$D$3)*(Realizado!$H13:$S13<>"")) | Q14: =IF(P14=0,"",K14) | R14: =IF(AND(Q14<>"",Q14<-1),-Q14+ROW()/1000000,"") | S14: =IF(Q14="","",I14)
A15: =Planejado!A14 | B15: =Planejado!B14 | C15: =Planejado!C14 | D15: =Planejado!D14 | E15: =Planejado!G14 | F15: =INDEX(Planejado!$H14:$S14,$D$3) | G15: =INDEX(Realizado!$H14:$S14,$D$3) | H15: =G15-F15 | I15: =SUMPRODUCT((COLUMN(Planejado!$H$4:$S$4)-COLUMN(Planejado!$H$4)+1<=$D$3)*Planejado!$H14:$S14) | J15: =SUMPRODUCT((COLUMN(Realizado!$H$4:$S$4)-COLUMN(Realizado!$H$4)+1<=$D$3)*Realizado!$H14:$S14) | K15: =J15-I15 | L15: =IFERROR(K15/I15,"") | M15: =IFERROR(J15/I15,"") | N15: =IF(P15=0,"Sem lançamento",IF(AND(I15=0,J15=0),"—",IF(I15=0,"Não orçado",IF(K15>0.05*I15,"Acima do orçado",IF(K15<-0.05*I15,"Abaixo do orçado","Dentro do orçado"))))) | O15: =IF(K15>1,K15+ROW()/1000000,"") | P15: =SUMPRODUCT((COLUMN(Realizado!$H$4:$S$4)-COLUMN(Realizado!$H$4)+1<=$D$3)*(Realizado!$H14:$S14<>"")) | Q15: =IF(P15=0,"",K15) | R15: =IF(AND(Q15<>"",Q15<-1),-Q15+ROW()/1000000,"") | S15: =IF(Q15="","",I15)
A16: =Planejado!A15 | B16: =Planejado!B15 | C16: =Planejado!C15 | D16: =Planejado!D15 | E16: =Planejado!G15 | F16: =INDEX(Planejado!$H15:$S15,$D$3) | G16: =INDEX(Realizado!$H15:$S15,$D$3) | H16: =G16-F16 | I16: =SUMPRODUCT((COLUMN(Planejado!$H$4:$S$4)-COLUMN(Planejado!$H$4)+1<=$D$3)*Planejado!$H15:$S15) | J16: =SUMPRODUCT((COLUMN(Realizado!$H$4:$S$4)-COLUMN(Realizado!$H$4)+1<=$D$3)*Realizado!$H15:$S15) | K16: =J16-I16 | L16: =IFERROR(K16/I16,"") | M16: =IFERROR(J16/I16,"") | N16: =IF(P16=0,"Sem lançamento",IF(AND(I16=0,J16=0),"—",IF(I16=0,"Não orçado",IF(K16>0.05*I16,"Acima do orçado",IF(K16<-0.05*I16,"Abaixo do orçado","Dentro do orçado"))))) | O16: =IF(K16>1,K16+ROW()/1000000,"") | P16: =SUMPRODUCT((COLUMN(Realizado!$H$4:$S$4)-COLUMN(Realizado!$H$4)+1<=$D$3)*(Realizado!$H15:$S15<>"")) | Q16: =IF(P16=0,"",K16) | R16: =IF(AND(Q16<>"",Q16<-1),-Q16+ROW()/1000000,"") | S16: =IF(Q16="","",I16)
A17: =Planejado!A16 | B17: =Planejado!B16 | C17: =Planejado!C16 | D17: =Planejado!D16 | E17: =Planejado!G16 | F17: =INDEX(Planejado!$H16:$S16,$D$3) | G17: =INDEX(Realizado!$H16:$S16,$D$3) | H17: =G17-F17 | I17: =SUMPRODUCT((COLUMN(Planejado!$H$4:$S$4)-COLUMN(Planejado!$H$4)+1<=$D$3)*Planejado!$H16:$S16) | J17: =SUMPRODUCT((COLUMN(Realizado!$H$4:$S$4)-COLUMN(Realizado!$H$4)+1<=$D$3)*Realizado!$H16:$S16) | K17: =J17-I17 | L17: =IFERROR(K17/I17,"") | M17: =IFERROR(J17/I17,"") | N17: =IF(P17=0,"Sem lançamento",IF(AND(I17=0,J17=0),"—",IF(I17=0,"Não orçado",IF(K17>0.05*I17,"Acima do orçado",IF(K17<-0.05*I17,"Abaixo do orçado","Dentro do orçado"))))) | O17: =IF(K17>1,K17+ROW()/1000000,"") | P17: =SUMPRODUCT((COLUMN(Realizado!$H$4:$S$4)-COLUMN(Realizado!$H$4)+1<=$D$3)*(Realizado!$H16:$S16<>"")) | Q17: =IF(P17=0,"",K17) | R17: =IF(AND(Q17<>"",Q17<-1),-Q17+ROW()/1000000,"") | S17: =IF(Q17="","",I17)
A18: =Planejado!A17 | B18: =Planejado!B17 | C18: =Planejado!C17 | D18: =Planejado!D17 | E18: =Planejado!G17 | F18: =INDEX(Planejado!$H17:$S17,$D$3) | G18: =INDEX(Realizado!$H17:$S17,$D$3) | H18: =G18-F18 | I18: =SUMPRODUCT((COLUMN(Planejado!$H$4:$S$4)-COLUMN(Planejado!$H$4)+1<=$D$3)*Planejado!$H17:$S17) | J18: =SUMPRODUCT((COLUMN(Realizado!$H$4:$S$4)-COLUMN(Realizado!$H$4)+1<=$D$3)*Realizado!$H17:$S17) | K18: =J18-I18 | L18: =IFERROR(K18/I18,"") | M18: =IFERROR(J18/I18,"") | N18: =IF(P18=0,"Sem lançamento",IF(AND(I18=0,J18=0),"—",IF(I18=0,"Não orçado",IF(K18>0.05*I18,"Acima do orçado",IF(K18<-0.05*I18,"Abaixo do orçado","Dentro do orçado"))))) | O18: =IF(K18>1,K18+ROW()/1000000,"") | P18: =SUMPRODUCT((COLUMN(Realizado!$H$4:$S$4)-COLUMN(Realizado!$H$4)+1<=$D$3)*(Realizado!$H17:$S17<>"")) | Q18: =IF(P18=0,"",K18) | R18: =IF(AND(Q18<>"",Q18<-1),-Q18+ROW()/1000000,"") | S18: =IF(Q18="","",I18)
A19: =Planejado!A18 | B19: =Planejado!B18 | C19: =Planejado!C18 | D19: =Planejado!D18 | E19: =Planejado!G18 | F19: =INDEX(Planejado!$H18:$S18,$D$3) | G19: =INDEX(Realizado!$H18:$S18,$D$3) | H19: =G19-F19 | I19: =SUMPRODUCT((COLUMN(Planejado!$H$4:$S$4)-COLUMN(Planejado!$H$4)+1<=$D$3)*Planejado!$H18:$S18) | J19: =SUMPRODUCT((COLUMN(Realizado!$H$4:$S$4)-COLUMN(Realizado!$H$4)+1<=$D$3)*Realizado!$H18:$S18) | K19: =J19-I19 | L19: =IFERROR(K19/I19,"") | M19: =IFERROR(J19/I19,"") | N19: =IF(P19=0,"Sem lançamento",IF(AND(I19=0,J19=0),"—",IF(I19=0,"Não orçado",IF(K19>0.05*I19,"Acima do orçado",IF(K19<-0.05*I19,"Abaixo do orçado","Dentro do orçado"))))) | O19: =IF(K19>1,K19+ROW()/1000000,"") | P19: =SUMPRODUCT((COLUMN(Realizado!$H$4:$S$4)-COLUMN(Realizado!$H$4)+1<=$D$3)*(Realizado!$H18:$S18<>"")) | Q19: =IF(P19=0,"",K19) | R19: =IF(AND(Q19<>"",Q19<-1),-Q19+ROW()/1000000,"") | S19: =IF(Q19="","",I19)
... A30: =Planejado!A29 | B30: =Planejado!B29 | C30: =Planejado!C29 | D30: =Planejado!D29 | E30: =Planejado!G29 | F30: =INDEX(Planejado!$H29:$S29,$D$3) | G30: =INDEX(Realizado!$H29:$S29,$D$3) | H30: =G30-F30 | I30: =SUMPRODUCT((COLUMN(Planejado!$H$4:$S$4)-COLUMN(Planejado!$H$4)+1<=$D$3)*Planejado!$H29:$S29) | J30: =SUMPRODUCT((COLUMN(Realizado!$H$4:$S$4)-COLUMN(Realizado!$H$4)+1<=$D$3)*Realizado!$H29:$S29) | K30: =J30-I30 | L30: =IFERROR(K30/I30,"") | M30: =IFERROR(J30/I30,"") | N30: =IF(P30=0,"Sem lançamento",IF(AND(I30=0,J30=0),"—",IF(I30=0,"Não orçado",IF(K30>0.05*I30,"Acima do orçado",IF(K30<-0.05*I30,"Abaixo do orçado","Dentro do orçado"))))) | O30: =IF(K30>1,K30+ROW()/1000000,"") | P30: =SUMPRODUCT((COLUMN(Realizado!$H$4:$S$4)-COLUMN(Realizado!$H$4)+1<=$D$3)*(Realizado!$H29:$S29<>"")) | Q30: =IF(P30=0,"",K30) | R30: =IF(AND(Q30<>"",Q30<-1),-Q30+ROW()/1000000,"") | S30: =IF(Q30="","",I30)
A31: TOTAL GERAL | F31: =SUM(F6:F30) | G31: =SUM(G6:G30) | H31: =SUM(H6:H30) | I31: =SUM(I6:I30) | J31: =SUM(J6:J30) | K31: =SUM(K6:K30) | L31: =IFERROR(K31/I31,"") | M31: =IFERROR(J31/I31,"")

Sheet Planejado
A1: ORÇAMENTO PLANEJADO 2026 — JURÍDICO E TI
A2: Base: janeiro a dezembro/2026 (12 meses). CLT com encargos de folha + benefícios inclusos. Esta aba é a referência — altere aqui apenas se o orçamento for oficialmente revisado.
A4: ID | B4: Departamento | C4: Bloco | D4: Descrição | E4: Detalhe / Observação | F4: Vínculo | G4: Plano de Contas | H4: Jan/26 | I4: Fev/26 | J4: Mar/26 | K4: Abr/26 | L4: Mai/26 | M4: Jun/26 | N4: Jul/26 | O4: Ago/26 | P4: Set/26 | Q4: Out/26 | R4: Nov/26 | S4: Dez/26 | T4: TOTAL DO ANO
A5: JUR-E01 | B5: Jurídico | C5: Equipe | D5: Miguel Clepf | E5: Advogado Júnior | F5: PJ | G5: Pessoal - PJ | H5: 10000 | I5: 10000 | J5: 10000 | K5: 10000 | L5: 10000 | M5: 10000 | N5: 10000 | O5: 10000 | P5: 10000 | Q5: 10000 | R5: 10000 | S5: 10000 | T5: =SUM(H5:S5)
A6: JUR-E02 | B6: Jurídico | C6: Equipe | D6: Geovanna | E6: Analista Administrativo — orçada pelo custo total (encargos de folha + benefícios). Salário bruto informado: R$ 2.886,91/mês | F6: CLT | G6: Pessoal - CLT | H6: 4825.515 | I6: 4825.515 | J6: 4825.515 | K6: 4825.515 | L6: 4825.515 | M6: 4825.515 | N6: 4825.515 | O6: 4825.515 | P6: 4825.515 | Q6: 4825.515 | R6: 4825.515 | S6: 4825.515 | T6: =SUM(H6:S6)
A7: JUR-E03 | B7: Jurídico | C7: Equipe | D7: Thamar Victória | E7: Advogada — recebia R$ 4.500/mês em jan–mar e passou a R$ 5.500 em abr/26 (aumento de R$ 1.000), contra R$ 5.000 orçados. Planejado revisado para R$ 5.500 a partir de ago/26 | F7: PJ | G7: Pessoal - PJ | H7: 5000 | I7: 5000 | J7: 5000 | K7: 5000 | L7: 5000 | M7: 5000 | N7: 5000 | O7: 5500 | P7: 5500 | Q7: 5500 | R7: 5500 | S7: 5500 | T7: =SUM(H7:S7)
A8: JUR-D01 | B8: Jurídico | C8: Despesas | D8: JUSFY | E8: Fase de teste com objetivo de eliminar o Astrea | G8: Licenças de Softwares | H8: 100 | I8: 100 | J8: 100 | K8: 100 | L8: 100 | M8: 100 | N8: 100 | O8: 100 | P8: 100 | Q8: 100 | R8: 100 | S8: 100 | T8: =SUM(H8:S8)
A9: JUR-D02 | B9: Jurídico | C9: Despesas | D9: JUSBRASIL | E9: ORÇAMENTO VEIO ERRADO: orçado R$ 104,90/mês, custo real R$ 136,00/mês. Corrigir na revisão orçamentária | G9: Licenças de Softwares | H9: 104.9 | I9: 104.9 | J9: 104.9 | K9: 104.9 | L9: 104.9 | M9: 104.9 | N9: 104.9 | O9: 104.9 | P9: 104.9 | Q9: 104.9 | R9: 104.9 | S9: 104.9 | T9: =SUM(H9:S9)
A10: JUR-D03 | B10: Jurídico | C10: Despesas | D10: ASTREA | E10: ORÇAMENTO VEIO ERRADO: orçado R$ 112,07/mês, custo real R$ 346,00/mês. Corrigir na revisão orçamentária | G10: Licenças de Softwares | H10: 112.07 | I10: 112.07 | J10: 112.07 | K10: 112.07 | L10: 112.07 | M10: 112.07 | N10: 112.07 | O10: 112.07 | P10: 112.07 | Q10: 112.07 | R10: 112.07 | S10: 112.07 | T10: =SUM(H10:S10)
A11: JUR-D04 | B11: Jurídico | C11: Despesas | D11: LEME | G11: Licenças de Softwares | H11: 1030 | I11: 1030 | J11: 1030 | K11: 1030 | L11: 1030 | M11: 1030 | N11: 1030 | O11: 1030 | P11: 1030 | Q11: 1030 | R11: 1030 | S11: 1030 | T11: =SUM(H11:S11)
A12: JUR-D05 | B12: Jurídico | C12: Despesas | D12: Cursos / Eventos / Network | G12: Custeio de Treinamento | H12: 1000 | I12: 1000 | J12: 1000 | K12: 1000 | L12: 1000 | M12: 1000 | N12: 1000 | O12: 1000 | P12: 1000 | Q12: 1000 | R12: 1000 | S12: 1000 | T12: =SUM(H12:S12)
A13: JUR-D06 | B13: Jurídico | C13: Despesas | D13: Bonificações trimestrais/semestrais do time | E13: Participação em projetos e atingimento de resultados — CONFIRMAR se houve parcela no 1º quadrimestre | G13: Prêmios | H13: 0 | I13: 0 | J13: 0 | K13: 0 | L13: 0 | M13: 0 | N13: 0 | O13: 10293.6 | P13: 0 | Q13: 0 | R13: 0 | S13: 12867 | T13: =SUM(H13:S13)
A14: TI-E01 | B14: TI | C14: Equipe | D14: Vinicius Di Franco | E14: Analista Administrativo — orçado pelo custo total (encargos de folha + benefícios). Salário bruto: R$ 2.570,52/mês até jul/26 e R$ 3.070,52 a partir de 05/08/26, aumento absorvido pela folga do envelope | F14: CLT | G14: Pessoal - CLT | H14: 5416.525 | I14: 5416.525 | J14: 5416.525 | K14: 5416.525 | L14: 5416.525 | M14: 5416.525 | N14: 5416.525 | O14: 5416.525 | P14: 5416.525 | Q14: 5416.525 | R14: 5416.525 | S14: 5416.525 | T14: =SUM(H14:S14)
A15: TI-E02 | B15: TI | C15: Equipe | D15: Elias Benedito | E15: Suporte Técnico Terceirizado | F15: PJ | G15: Pessoal - PJ | H15: 1065 | I15: 1065 | J15: 1065 | K15: 1065 | L15: 1065 | M15: 1065 | N15: 1065 | O15: 1065 | P15: 1065 | Q15: 1065 | R15: 1065 | S15: 1065 | T15: =SUM(H15:S15)
A16: TI-E03 | B16: TI | C16: Equipe | D16: Jonathan | E16: Consultor — entrada em abr/26 (9 meses), conforme o total da ficha original | F16: PJ | G16: Pessoal - PJ | H16: 0 | I16: 0 | J16: 0 | K16: 10000 | L16: 10000 | M16: 10000 | N16: 10000 | O16: 10000 | P16: 10000 | Q16: 10000 | R16: 10000 | S16: 10000 | T16: =SUM(H16:S16)
A17: TI-D01 | B17: TI | C17: Despesas | D17: Peças de Manutenção | E17: Tela, teclado, carcaça, mouses de reposição, carregadores etc. | G17: Equipamentos Eletrônicos Diversos | H17: 810 | I17: 810 | J17: 810 | K17: 810 | L17: 810 | M17: 810 | N17: 810 | O17: 810 | P17: 810 | Q17: 810 | R17: 810 | S17: 810 | T17: =SUM(H17:S17)
A18: TI-D02 | B18: TI | C18: Despesas | D18: Backup em Nuvem | E18: Serviço de backup em nuvem para servidor — RATEIO A DEFINIR | G18: Licenças de Softwares | H18: 825 | I18: 825 | J18: 825 | K18: 825 | L18: 825 | M18: 825 | N18: 825 | O18: 825 | P18: 825 | Q18: 825 | R18: 825 | S18: 825 | T18: =SUM(H18:S18)
A19: TI-D03 | B19: TI | C19: Despesas | D19: Inteligência Artificial (Adapta) | E19: Plataforma de IA para utilização de agentes — RATEIO A DEFINIR | G19: Licenças de Softwares | H19: 1300 | I19: 1300 | J19: 1300 | K19: 1300 | L19: 1300 | M19: 1300 | N19: 1600 | O19: 1600 | P19: 1600 | Q19: 1600 | R19: 1600 | S19: 1600 | T19: =SUM(H19:S19)
A20: TI-D04 | B20: TI | C20: Despesas | D20: Antivírus | E20: Proteção para equipamentos — RATEIO A DEFINIR | G20: Licenças de Softwares | H20: 240 | I20: 240 | J20: 240 | K20: 240 | L20: 240 | M20: 240 | N20: 240 | O20: 240 | P20: 240 | Q20: 240 | R20: 240 | S20: 240 | T20: =SUM(H20:S20)
A21: TI-D05 | B21: TI | C21: Despesas | D21: Pacote Office 365 | E21: Licenças de software (conferir nº de licenças x usuários) — RATEIO A DEFINIR | G21: Licenças de Softwares | H21: 375 | I21: 375 | J21: 375 | K21: 375 | L21: 375 | M21: 375 | N21: 375 | O21: 375 | P21: 375 | Q21: 375 | R21: 375 | S21: 375 | T21: =SUM(H21:S21)
A22: TI-D06 | B22: TI | C22: Despesas | D22: Projeto Melhoria de Infraestrutura - Sala de Reunião | E22: Cadeiras, cafeteira, copos, canetas, blocos personalizados, câmeras, microfones etc. | G22: Móveis e Utensílios | H22: 2800 | I22: 2800 | J22: 2800 | K22: 2800 | L22: 2800 | M22: 2800 | N22: 2800 | O22: 2800 | P22: 2800 | Q22: 2800 | R22: 2800 | S22: 2800 | T22: =SUM(H22:S22)
A23: TI-D07 | B23: TI | C23: Despesas | D23: Cursos e Treinamentos | G23: Custeio de Treinamento | H23: 200 | I23: 200 | J23: 200 | K23: 200 | L23: 200 | M23: 200 | N23: 200 | O23: 200 | P23: 200 | Q23: 200 | R23: 200 | S23: 200 | T23: =SUM(H23:S23)
A24: TI-D08 | B24: TI | C24: Despesas | D24: Aplicativo de Gravação de Reunião | G24: Licenças de Softwares | H24: 220 | I24: 220 | J24: 220 | K24: 220 | L24: 220 | M24: 220 | N24: 220 | O24: 220 | P24: 220 | Q24: 220 | R24: 220 | S24: 220 | T24: =SUM(H24:S24)
A25: TI-D10 | B25: TI | C25: Despesas | D25: Claude | E25: Ferramenta de IA — não constava na ficha. Planejado a definir com a diretoria | G25: Licenças de Softwares | H25: 0 | I25: 0 | J25: 0 | K25: 0 | L25: 0 | M25: 0 | N25: 0 | O25: 0 | P25: 0 | Q25: 0 | R25: 0 | S25: 0 | T25: =SUM(H25:S25)
A26: TI-D11 | B26: TI | C26: Despesas | D26: GPT | E26: Ferramenta de IA — não constava na ficha. Planejado a definir com a diretoria | G26: Licenças de Softwares | H26: 0 | I26: 0 | J26: 0 | K26: 0 | L26: 0 | M26: 0 | N26: 0 | O26: 0 | P26: 0 | Q26: 0 | R26: 0 | S26: 0 | T26: =SUM(H26:S26)
A27: TI-D12 | B27: TI | C27: Despesas | D27: Adapta One | E27: Ferramenta de IA — não constava na ficha. Planejado a definir com a diretoria. CONFERIR sobreposição com a linha 'Inteligência Artificial (Adapta)' | G27: Licenças de Softwares | H27: 0 | I27: 0 | J27: 0 | K27: 0 | L27: 0 | M27: 0 | N27: 0 | O27: 0 | P27: 0 | Q27: 0 | R27: 0 | S27: 0 | T27: =SUM(H27:S27)
A28: TI-D13 | B28: TI | C28: Despesas | D28: Adapta Skip | E28: Ferramenta de IA — não constava na ficha. Planejado a definir com a diretoria. CONFERIR o nome exato do produto e a sobreposição com 'Inteligência Artificial (Adapta)' | G28: Licenças de Softwares | H28: 0 | I28: 0 | J28: 0 | K28: 0 | L28: 0 | M28: 0 | N28: 0 | O28: 0 | P28: 0 | Q28: 0 | R28: 0 | S28: 0 | T28: =SUM(H28:S28)
A29: TI-D09 | B29: TI | C29: Despesas | D29: Bonificação do time | E29: Cumprimento de prazos e participação em projetos — CONFIRMAR se houve parcela no 1º quadrimestre | G29: Prêmios | H29: 0 | I29: 0 | J29: 0 | K29: 0 | L29: 0 | M29: 0 | N29: 0 | O29: 2400 | P29: 0 | Q29: 0 | R29: 0 | S29: 3600 | T29: =SUM(H29:S29)
A30: TOTAL GERAL | H30: =SUM(H5:H29) | I30: =SUM(I5:I29) | J30: =SUM(J5:J29) | K30: =SUM(K5:K29) | L30: =SUM(L5:L29) | M30: =SUM(M5:M29) | N30: =SUM(N5:N29) | O30: =SUM(O5:O29) | ... T30: =SUM(T5:T29)

Sheet Realizado
A1: REALIZADO 2026 — JURÍDICO E TI
A2: Preencha SOMENTE as células amarelas (meses). As colunas de identificação vêm da aba Planejado. Lance o valor efetivamente pago/competência do mês. Mês sem gasto: digite 0 para diferenciar de 'ainda não lançado'.
A4: ID | B4: Departamento | C4: Bloco | D4: Descrição | E4: Detalhe / Observação | F4: Vínculo | G4: Plano de Contas | H4: Jan/26 | I4: Fev/26 | J4: Mar/26 | K4: Abr/26 | L4: Mai/26 | M4: Jun/26 | N4: Jul/26 | O4: Ago/26 | P4: Set/26 | Q4: Out/26 | R4: Nov/26 | S4: Dez/26 | T4: TOTAL REALIZADO | U4: Fonte do dado | V4: Observações do mês
A5: =Planejado!A5 | B5: =Planejado!B5 | C5: =Planejado!C5 | D5: =Planejado!D5 | E5: =Planejado!E5 | F5: =Planejado!F5 | G5: =Planejado!G5 | H5: 6750 | I5: 6750 | J5: 6750 | K5: 6750 | L5: 6750 | M5: 6750 | N5: 6750 | O5: 8818 | T5: =SUM(H5:S5) | U5: Gestora, 05/08/26 | V5: R$ 6.750/mês de jan a jul; R$ 8.818 pagos em 01/08 (ref. julho). Lançado por caixa
A6: =Planejado!A6 | B6: =Planejado!B6 | C6: =Planejado!C6 | D6: =Planejado!D6 | E6: =Planejado!E6 | F6: =Planejado!F6 | G6: =Planejado!G6 | H6: 2886.91 | I6: 2886.91 | J6: 2886.91 | K6: 2886.91 | L6: 2886.91 | M6: 2886.91 | N6: 2886.91 | T6: =SUM(H6:S6) | U6: Gestora, 05/08/26 | V6: SALÁRIO BRUTO, sem alteração no ano. O orçado é custo total, então o desvio desta linha NÃO é economia: faltam encargos e benefícios (~R$ 1.938,61/mês)
A7: =Planejado!A7 | B7: =Planejado!B7 | C7: =Planejado!C7 | D7: =Planejado!D7 | E7: =Planejado!E7 | F7: =Planejado!F7 | G7: =Planejado!G7 | H7: 4500 | I7: 4500 | J7: 4500 | K7: 5500 | L7: 5500 | M7: 5500 | N7: 5500 | T7: =SUM(H7:S7) | U7: Gestora, 05/08/26 | V7: R$ 4.500/mês em jan–mar; aumento de R$ 1.000 a partir de abr/26
A8: =Planejado!A8 | B8: =Planejado!B8 | C8: =Planejado!C8 | D8: =Planejado!D8 | E8: =Planejado!E8 | F8: =Planejado!F8 | G8: =Planejado!G8 | H8: 0 | I8: 0 | J8: 0 | K8: 0 | L8: 0 | M8: 0 | N8: 0 | T8: =SUM(H8:S8) | U8: Gestora, 05/08/26 | V8: Ainda não iniciado — sem cobrança
A9: =Planejado!A9 | B9: =Planejado!B9 | C9: =Planejado!C9 | D9: =Planejado!D9 | E9: =Planejado!E9 | F9: =Planejado!F9 | G9: =Planejado!G9 | H9: 136 | I9: 136 | J9: 136 | K9: 136 | L9: 136 | M9: 136 | N9: 136 | T9: =SUM(H9:S9) | U9: Gestora, 05/08/26 | V9: R$ 136,00/mês contra R$ 104,90 orçados. Erro no orçamento original
A10: =Planejado!A10 | B10: =Planejado!B10 | C10: =Planejado!C10 | D10: =Planejado!D10 | E10: =Planejado!E10 | F10: =Planejado!F10 | G10: =Planejado!G10 | H10: 346 | I10: 346 | J10: 346 | K10: 346 | L10: 346 | M10: 346 | N10: 346 | T10: =SUM(H10:S10) | U10: Gestora, 05/08/26 | V10: R$ 346,00/mês — 3x o orçado (R$ 112,07). Erro no orçamento original
A11: =Planejado!A11 | B11: =Planejado!B11 | C11: =Planejado!C11 | D11: =Planejado!D11 | E11: =Planejado!E11 | F11: =Planejado!F11 | G11: =Planejado!G11 | H11: 970 | I11: 970 | J11: 970 | K11: 970 | L11: 970 | M11: 970 | N11: 970 | T11: =SUM(H11:S11) | U11: Gestora, 05/08/26
A12: =Planejado!A12 | B12: =Planejado!B12 | C12: =Planejado!C12 | D12: =Planejado!D12 | E12: =Planejado!E12 | F12: =Planejado!F12 | G12: =Planejado!G12 | H12: 0 | I12: 0 | J12: 0 | K12: 0 | L12: 0 | M12: 0 | N12: 0 | T12: =SUM(H12:S12) | U12: Gestora, 05/08/26 | V12: Sem gasto no período
A13: =Planejado!A13 | B13: =Planejado!B13 | C13: =Planejado!C13 | D13: =Planejado!D13 | E13: =Planejado!E13 | F13: =Planejado!F13 | G13: =Planejado!G13 | H13: 0 | I13: 0 | J13: 0 | K13: 0 | L13: 0 | M13: 0 | N13: 0 | T13: =SUM(H13:S13) | U13: Gestora, 05/08/26 | V13: Sem parcela no 1º semestre; bonificação de ago/26 a confirmar
A14: =Planejado!A14 | B14: =Planejado!B14 | C14: =Planejado!C14 | D14: =Planejado!D14 | E14: =Planejado!E14 | F14: =Planejado!F14 | G14: =Planejado!G14 | T14: =SUM(H14:S14) | V14: PREENCHER com o CUSTO TOTAL. Bruto: R$ 2.570,52/mês até jul e R$ 3.070,52 de ago — faltam encargos e benefícios
A15: =Planejado!A15 | B15: =Planejado!B15 | C15: =Planejado!C15 | D15: =Planejado!D15 | E15: =Planejado!E15 | F15: =Planejado!F15 | G15: =Planejado!G15 | H15: 0 | I15: 0 | J15: 0 | K15: 0 | L15: 0 | M15: 0 | N15: 0 | T15: =SUM(H15:S15) | U15: Gestora, 05/08/26 | V15: Sem acionamento no período — confirmar se o contrato segue ativo
A16: =Planejado!A16 | B16: =Planejado!B16 | C16: =Planejado!C16 | D16: =Planejado!D16 | E16: =Planejado!E16 | F16: =Planejado!F16 | G16: =Planejado!G16 | H16: 0 | I16: 0 | J16: 0 | K16: 6300 | L16: 6300 | M16: 6300 | N16: 6300 | T16: =SUM(H16:S16) | U16: Gestora, 05/08/26 | V16: Entrada em abr/26. R$ 3.700/mês abaixo do contratado — confirmar escopo
A17: =Planejado!A17 | B17: =Planejado!B17 | C17: =Planejado!C17 | D17: =Planejado!D17 | E17: =Planejado!E17 | F17: =Planejado!F17 | G17: =Planejado!G17 | T17: =SUM(H17:S17)
A18: =Planejado!A18 | B18: =Planejado!B18 | C18: =Planejado!C18 | D18: =Planejado!D18 | E18: =Planejado!E18 | F18: =Planejado!F18 | G18: =Planejado!G18 | T18: =SUM(H18:S18)
A19: =Planejado!A19 | B19: =Planejado!B19 | C19: =Planejado!C19 | D19: =Planejado!D19 | E19: =Planejado!E19 | F19: =Planejado!F19 | G19: =Planejado!G19 | T19: =SUM(H19:S19)
A20: =Planejado!A20 | B20: =Planejado!B20 | C20: =Planejado!C20 | D20: =Planejado!D20 | E20: =Planejado!E20 | F20: =Planejado!F20 | G20: =Planejado!G20 | T20: =SUM(H20:S20)
A21: =Planejado!A21 | B21: =Planejado!B21 | C21: =Planejado!C21 | D21: =Planejado!D21 | E21: =Planejado!E21 | F21: =Planejado!F21 | G21: =Planejado!G21 | T21: =SUM(H21:S21)
A22: =Planejado!A22 | B22: =Planejado!B22 | C22: =Planejado!C22 | D22: =Planejado!D22 | E22: =Planejado!E22 | F22: =Planejado!F22 | G22: =Planejado!G22 | T22: =SUM(H22:S22)
A23: =Planejado!A23 | B23: =Planejado!B23 | C23: =Planejado!C23 | D23: =Planejado!D23 | E23: =Planejado!E23 | F23: =Planejado!F23 | G23: =Planejado!G23 | T23: =SUM(H23:S23)
A24: =Planejado!A24 | B24: =Planejado!B24 | C24: =Planejado!C24 | D24: =Planejado!D24 | E24: =Planejado!E24 | F24: =Planejado!F24 | G24: =Planejado!G24 | T24: =SUM(H24:S24)
A25: =Planejado!A25 | B25: =Planejado!B25 | C25: =Planejado!C25 | D25: =Planejado!D25 | E25: =Planejado!E25 | F25: =Planejado!F25 | G25: =Planejado!G25 | T25: =SUM(H25:S25)
A26: =Planejado!A26 | B26: =Planejado!B26 | C26: =Planejado!C26 | D26: =Planejado!D26 | E26: =Planejado!E26 | F26: =Planejado!F26 | G26: =Planejado!G26 | T26: =SUM(H26:S26)
A27: =Planejado!A27 | B27: =Planejado!B27 | C27: =Planejado!C27 | D27: =Planejado!D27 | E27: =Planejado!E27 | F27: =Planejado!F27 | G27: =Planejado!G27 | T27: =SUM(H27:S27)
A28: =Planejado!A28 | B28: =Planejado!B28 | C28: =Planejado!C28 | D28: =Planejado!D28 | E28: =Planejado!E28 | F28: =Planejado!F28 | G28: =Planejado!G28 | T28: =SUM(H28:S28)
A29: =Planejado!A29 | B29: =Planejado!B29 | C29: =Planejado!C29 | D29: =Planejado!D29 | E29: =Planejado!E29 | F29: =Planejado!F29 | G29: =Planejado!G29 | T29: =SUM(H29:S29)
A30: TOTAL GERAL | H30: =SUM(H5:H29) | I30: =SUM(I5:I29) | J30: =SUM(J5:J29) | K30: =SUM(K5:K29) | L30: =SUM(L5:L29) | M30: =SUM(M5:M29) | N30: =SUM(N5:N29) | O30: =SUM(O5:O29) | ... T30: =SUM(T5:T29)

Sheet Evolução Mensal
A1: EVOLUÇÃO MENSAL — Planejado x Realizado
A2: Visão mês a mês do consolidado e por departamento. Alimenta gráficos e a leitura de tendência.
A4: Mês | B4: Jurídico Plan. | C4: Jurídico Real. | D4: TI Plan. | E4: TI Real. | F4: Total Plan. | G4: Total Real. | H4: Desvio do mês (R$) | I4: Planejado acum. | J4: Realizado acum.
A5: Jan/26 | B5: =SUMIFS(Planejado!$H$5:$H$29,Planejado!$B$5:$B$29,"Jurídico") | C5: =SUMIFS(Realizado!$H$5:$H$29,Realizado!$B$5:$B$29,"Jurídico") | D5: =SUMIFS(Planejado!$H$5:$H$29,Planejado!$B$5:$B$29,"TI") | E5: =SUMIFS(Realizado!$H$5:$H$29,Realizado!$B$5:$B$29,"TI") | F5: =B5+D5 | G5: =C5+E5 | H5: =G5-F5 | I5: =SUM($F$5:F5) | J5: =SUM($G$5:G5)
A6: Fev/26 | B6: =SUMIFS(Planejado!$I$5:$I$29,Planejado!$B$5:$B$29,"Jurídico") | C6: =SUMIFS(Realizado!$I$5:$I$29,Realizado!$B$5:$B$29,"Jurídico") | D6: =SUMIFS(Planejado!$I$5:$I$29,Planejado!$B$5:$B$29,"TI") | E6: =SUMIFS(Realizado!$I$5:$I$29,Realizado!$B$5:$B$29,"TI") | F6: =B6+D6 | G6: =C6+E6 | H6: =G6-F6 | I6: =SUM($F$5:F6) | J6: =SUM($G$5:G6)
A7: Mar/26 | B7: =SUMIFS(Planejado!$J$5:$J$29,Planejado!$B$5:$B$29,"Jurídico") | C7: =SUMIFS(Realizado!$J$5:$J$29,Realizado!$B$5:$B$29,"Jurídico") | D7: =SUMIFS(Planejado!$J$5:$J$29,Planejado!$B$5:$B$29,"TI") | E7: =SUMIFS(Realizado!$J$5:$J$29,Realizado!$B$5:$B$29,"TI") | F7: =B7+D7 | G7: =C7+E7 | H7: =G7-F7 | I7: =SUM($F$5:F7) | J7: =SUM($G$5:G7)
A8: Abr/26 | B8: =SUMIFS(Planejado!$K$5:$K$29,Planejado!$B$5:$B$29,"Jurídico") | C8: =SUMIFS(Realizado!$K$5:$K$29,Realizado!$B$5:$B$29,"Jurídico") | D8: =SUMIFS(Planejado!$K$5:$K$29,Planejado!$B$5:$B$29,"TI") | E8: =SUMIFS(Realizado!$K$5:$K$29,Realizado!$B$5:$B$29,"TI") | F8: =B8+D8 | G8: =C8+E8 | H8: =G8-F8 | I8: =SUM($F$5:F8) | J8: =SUM($G$5:G8)
A9: Mai/26 | B9: =SUMIFS(Planejado!$L$5:$L$29,Planejado!$B$5:$B$29,"Jurídico") | C9: =SUMIFS(Realizado!$L$5:$L$29,Realizado!$B$5:$B$29,"Jurídico") | D9: =SUMIFS(Planejado!$L$5:$L$29,Planejado!$B$5:$B$29,"TI") | E9: =SUMIFS(Realizado!$L$5:$L$29,Realizado!$B$5:$B$29,"TI") | F9: =B9+D9 | G9: =C9+E9 | H9: =G9-F9 | I9: =SUM($F$5:F9) | J9: =SUM($G$5:G9)
A10: Jun/26 | B10: =SUMIFS(Planejado!$M$5:$M$29,Planejado!$B$5:$B$29,"Jurídico") | C10: =SUMIFS(Realizado!$M$5:$M$29,Realizado!$B$5:$B$29,"Jurídico") | D10: =SUMIFS(Planejado!$M$5:$M$29,Planejado!$B$5:$B$29,"TI") | E10: =SUMIFS(Realizado!$M$5:$M$29,Realizado!$B$5:$B$29,"TI") | F10: =B10+D10 | G10: =C10+E10 | H10: =G10-F10 | I10: =SUM($F$5:F10) | J10: =SUM($G$5:G10)
A11: Jul/26 | B11: =SUMIFS(Planejado!$N$5:$N$29,Planejado!$B$5:$B$29,"Jurídico") | C11: =SUMIFS(Realizado!$N$5:$N$29,Realizado!$B$5:$B$29,"Jurídico") | D11: =SUMIFS(Planejado!$N$5:$N$29,Planejado!$B$5:$B$29,"TI") | E11: =SUMIFS(Realizado!$N$5:$N$29,Realizado!$B$5:$B$29,"TI") | F11: =B11+D11 | G11: =C11+E11 | H11: =G11-F11 | I11: =SUM($F$5:F11) | J11: =SUM($G$5:G11)
A12: Ago/26 | B12: =SUMIFS(Planejado!$O$5:$O$29,Planejado!$B$5:$B$29,"Jurídico") | C12: =SUMIFS(Realizado!$O$5:$O$29,Realizado!$B$5:$B$29,"Jurídico") | D12: =SUMIFS(Planejado!$O$5:$O$29,Planejado!$B$5:$B$29,"TI") | E12: =SUMIFS(Realizado!$O$5:$O$29,Realizado!$B$5:$B$29,"TI") | F12: =B12+D12 | G12: =C12+E12 | H12: =G12-F12 | I12: =SUM($F$5:F12) | J12: =SUM($G$5:G12)
A13: Set/26 | B13: =SUMIFS(Planejado!$P$5:$P$29,Planejado!$B$5:$B$29,"Jurídico") | C13: =SUMIFS(Realizado!$P$5:$P$29,Realizado!$B$5:$B$29,"Jurídico") | D13: =SUMIFS(Planejado!$P$5:$P$29,Planejado!$B$5:$B$29,"TI") | E13: =SUMIFS(Realizado!$P$5:$P$29,Realizado!$B$5:$B$29,"TI") | F13: =B13+D13 | G13: =C13+E13 | H13: =G13-F13 | I13: =SUM($F$5:F13) | J13: =SUM($G$5:G13)
A14: Out/26 | B14: =SUMIFS(Planejado!$Q$5:$Q$29,Planejado!$B$5:$B$29,"Jurídico") | C14: =SUMIFS(Realizado!$Q$5:$Q$29,Realizado!$B$5:$B$29,"Jurídico") | D14: =SUMIFS(Planejado!$Q$5:$Q$29,Planejado!$B$5:$B$29,"TI") | E14: =SUMIFS(Realizado!$Q$5:$Q$29,Realizado!$B$5:$B$29,"TI") | F14: =B14+D14 | G14: =C14+E14 | H14: =G14-F14 | I14: =SUM($F$5:F14) | J14: =SUM($G$5:G14)
A15: Nov/26 | B15: =SUMIFS(Planejado!$R$5:$R$29,Planejado!$B$5:$B$29,"Jurídico") | C15: =SUMIFS(Realizado!$R$5:$R$29,Realizado!$B$5:$B$29,"Jurídico") | D15: =SUMIFS(Planejado!$R$5:$R$29,Planejado!$B$5:$B$29,"TI") | E15: =SUMIFS(Realizado!$R$5:$R$29,Realizado!$B$5:$B$29,"TI") | F15: =B15+D15 | G15: =C15+E15 | H15: =G15-F15 | I15: =SUM($F$5:F15) | J15: =SUM($G$5:G15)
A16: Dez/26 | B16: =SUMIFS(Planejado!$S$5:$S$29,Planejado!$B$5:$B$29,"Jurídico") | C16: =SUMIFS(Realizado!$S$5:$S$29,Realizado!$B$5:$B$29,"Jurídico") | D16: =SUMIFS(Planejado!$S$5:$S$29,Planejado!$B$5:$B$29,"TI") | E16: =SUMIFS(Realizado!$S$5:$S$29,Realizado!$B$5:$B$29,"TI") | F16: =B16+D16 | G16: =C16+E16 | H16: =G16-F16 | I16: =SUM($F$5:F16) | J16: =SUM($G$5:G16)
A17: TOTAL | B17: =SUM(B5:B16) | C17: =SUM(C5:C16) | D17: =SUM(D5:D16) | E17: =SUM(E5:E16) | F17: =SUM(F5:F16) | G17: =SUM(G5:G16) | H17: =SUM(H5:H16)

Sheet Por Plano de Contas
A1: RESUMO POR PLANO DE CONTAS
A2: Mesma referência de mês da aba Comparativo (B3). Serve para conversar com o financeiro na linguagem do plano de contas.
A4: Plano de Contas | B4: Jurídico — Plan. | C4: Jurídico — Real. | D4: TI — Plan. | E4: TI — Real. | F4: Total Planejado acum. | G4: Total Realizado acum. | H4: Desvio (R$) | I4: Desvio (%) | J4: Orçado do ano
A5: Pessoal - CLT | B5: =SUMIFS(Comparativo!$I$6:$I$30,Comparativo!$E$6:$E$30,$A5,Comparativo!$B$6:$B$30,"Jurídico") | C5: =SUMIFS(Comparativo!$J$6:$J$30,Comparativo!$E$6:$E$30,$A5,Comparativo!$B$6:$B$30,"Jurídico") | D5: =SUMIFS(Comparativo!$I$6:$I$30,Comparativo!$E$6:$E$30,$A5,Comparativo!$B$6:$B$30,"TI") | E5: =SUMIFS(Comparativo!$J$6:$J$30,Comparativo!$E$6:$E$30,$A5,Comparativo!$B$6:$B$30,"TI") | F5: =B5+D5 | G5: =C5+E5 | H5: =G5-F5 | I5: =IFERROR(H5/F5,"") | J5: =SUMIFS(Planejado!$T$5:$T$29,Planejado!$G$5:$G$29,$A5)
A6: Pessoal - PJ | B6: =SUMIFS(Comparativo!$I$6:$I$30,Comparativo!$E$6:$E$30,$A6,Comparativo!$B$6:$B$30,"Jurídico") | C6: =SUMIFS(Comparativo!$J$6:$J$30,Comparativo!$E$6:$E$30,$A6,Comparativo!$B$6:$B$30,"Jurídico") | D6: =SUMIFS(Comparativo!$I$6:$I$30,Comparativo!$E$6:$E$30,$A6,Comparativo!$B$6:$B$30,"TI") | E6: =SUMIFS(Comparativo!$J$6:$J$30,Comparativo!$E$6:$E$30,$A6,Comparativo!$B$6:$B$30,"TI") | F6: =B6+D6 | G6: =C6+E6 | H6: =G6-F6 | I6: =IFERROR(H6/F6,"") | J6: =SUMIFS(Planejado!$T$5:$T$29,Planejado!$G$5:$G$29,$A6)
A7: Licenças de Softwares | B7: =SUMIFS(Comparativo!$I$6:$I$30,Comparativo!$E$6:$E$30,$A7,Comparativo!$B$6:$B$30,"Jurídico") | C7: =SUMIFS(Comparativo!$J$6:$J$30,Comparativo!$E$6:$E$30,$A7,Comparativo!$B$6:$B$30,"Jurídico") | D7: =SUMIFS(Comparativo!$I$6:$I$30,Comparativo!$E$6:$E$30,$A7,Comparativo!$B$6:$B$30,"TI") | E7: =SUMIFS(Comparativo!$J$6:$J$30,Comparativo!$E$6:$E$30,$A7,Comparativo!$B$6:$B$30,"TI") | F7: =B7+D7 | G7: =C7+E7 | H7: =G7-F7 | I7: =IFERROR(H7/F7,"") | J7: =SUMIFS(Planejado!$T$5:$T$29,Planejado!$G$5:$G$29,$A7)
A8: Custeio de Treinamento | B8: =SUMIFS(Comparativo!$I$6:$I$30,Comparativo!$E$6:$E$30,$A8,Comparativo!$B$6:$B$30,"Jurídico") | C8: =SUMIFS(Comparativo!$J$6:$J$30,Comparativo!$E$6:$E$30,$A8,Comparativo!$B$6:$B$30,"Jurídico") | D8: =SUMIFS(Comparativo!$I$6:$I$30,Comparativo!$E$6:$E$30,$A8,Comparativo!$B$6:$B$30,"TI") | E8: =SUMIFS(Comparativo!$J$6:$J$30,Comparativo!$E$6:$E$30,$A8,Comparativo!$B$6:$B$30,"TI") | F8: =B8+D8 | G8: =C8+E8 | H8: =G8-F8 | I8: =IFERROR(H8/F8,"") | J8: =SUMIFS(Planejado!$T$5:$T$29,Planejado!$G$5:$G$29,$A8)
A9: Prêmios | B9: =SUMIFS(Comparativo!$I$6:$I$30,Comparativo!$E$6:$E$30,$A9,Comparativo!$B$6:$B$30,"Jurídico") | C9: =SUMIFS(Comparativo!$J$6:$J$30,Comparativo!$E$6:$E$30,$A9,Comparativo!$B$6:$B$30,"Jurídico") | D9: =SUMIFS(Comparativo!$I$6:$I$30,Comparativo!$E$6:$E$30,$A9,Comparativo!$B$6:$B$30,"TI") | E9: =SUMIFS(Comparativo!$J$6:$J$30,Comparativo!$E$6:$E$30,$A9,Comparativo!$B$6:$B$30,"TI") | F9: =B9+D9 | G9: =C9+E9 | H9: =G9-F9 | I9: =IFERROR(H9/F9,"") | J9: =SUMIFS(Planejado!$T$5:$T$29,Planejado!$G$5:$G$29,$A9)
A10: Equipamentos Eletrônicos Diversos | B10: =SUMIFS(Comparativo!$I$6:$I$30,Comparativo!$E$6:$E$30,$A10,Comparativo!$B$6:$B$30,"Jurídico") | C10: =SUMIFS(Comparativo!$J$6:$J$30,Comparativo!$E$6:$E$30,$A10,Comparativo!$B$6:$B$30,"Jurídico") | D10: =SUMIFS(Comparativo!$I$6:$I$30,Comparativo!$E$6:$E$30,$A10,Comparativo!$B$6:$B$30,"TI") | E10: =SUMIFS(Comparativo!$J$6:$J$30,Comparativo!$E$6:$E$30,$A10,Comparativo!$B$6:$B$30,"TI") | F10: =B10+D10 | G10: =C10+E10 | H10: =G10-F10 | I10: =IFERROR(H10/F10,"") | J10: =SUMIFS(Planejado!$T$5:$T$29,Planejado!$G$5:$G$29,$A10)
A11: Móveis e Utensílios | B11: =SUMIFS(Comparativo!$I$6:$I$30,Comparativo!$E$6:$E$30,$A11,Comparativo!$B$6:$B$30,"Jurídico") | C11: =SUMIFS(Comparativo!$J$6:$J$30,Comparativo!$E$6:$E$30,$A11,Comparativo!$B$6:$B$30,"Jurídico") | D11: =SUMIFS(Comparativo!$I$6:$I$30,Comparativo!$E$6:$E$30,$A11,Comparativo!$B$6:$B$30,"TI") | E11: =SUMIFS(Comparativo!$J$6:$J$30,Comparativo!$E$6:$E$30,$A11,Comparativo!$B$6:$B$30,"TI") | F11: =B11+D11 | G11: =C11+E11 | H11: =G11-F11 | I11: =IFERROR(H11/F11,"") | J11: =SUMIFS(Planejado!$T$5:$T$29,Planejado!$G$5:$G$29,$A11)
A12: TOTAL | B12: =SUM(B5:B11) | C12: =SUM(C5:C11) | D12: =SUM(D5:D11) | E12: =SUM(E5:E11) | F12: =SUM(F5:F11) | G12: =SUM(G5:G11) | H12: =SUM(H5:H11) | I12: =IFERROR(H12/F12,"") | J12: =SUM(J5:J11)

Sheet Pendências
A1: PENDÊNCIAS E DECISÕES EM ABERTO
A2: Pontos que precisam ser fechados para o comparativo ficar confiável. Atualize a coluna Status conforme forem resolvidos.
A4: # | B4: Tema | C4: O que está em aberto | D4: Impacto no comparativo | E4: Responsável | F4: Status
A5: A | B5: Geovanna — realizado em base diferente do orçado | C5: O planejado dela é R$ 4.825,52/mês, que é o CUSTO TOTAL orçado na ficha (salário + encargos de folha + benefícios). O realizado lançado é o SALÁRIO BRUTO, R$ 2.886,91/mês, confirmado sem alteração no ano. São bases diferentes. | D5: O desvio desta linha (−R$ 1.938,61/mês, −R$ 13.570,24 no acumulado jan–jul) NÃO é economia: é o encargo que falta do lado do realizado. Para fechar, peça ao RH o custo total mensal dela — ou o percentual de encargos da empresa, que dá para calcular a partir do bruto. | E5: Cristiane + RH | F5: BASE DIFERENTE
A6: B | B6: Vinicius — custo total A LANÇAR | C6: Mesmo caso da Geovanna. O planejado é R$ 5.416,525/mês (custo total). Brutos confirmados: R$ 2.570,52 até jul/26 e R$ 3.070,52 a partir de 05/08/26 — o aumento é absorvido pela folga do envelope, que já previa reajuste, então o orçado não muda. O realizado está em branco. | D6: A folga do orçado NÃO é economia estrutural. Com o bruto de agosto, sobram R$ 2.346,01 para encargos, o que equivale a 76% sobre o bruto — dentro da faixa normal (67% a 80%), então pode sobrar ou estourar. Só o custo total real vai dizer. | E6: Cristiane + RH | F6: A LANÇAR
A7: C | B7: Aumento da Thamar em abr/26 | C7: Recebia R$ 4.500/mês de jan a mar, abaixo dos R$ 5.000 orçados. Em abr/26 teve aumento de R$ 1.000 e passou a R$ 5.500, acima do orçado. O planejado foi mantido em R$ 5.000 nos sete meses fechados (para o desvio ficar visível) e revisado para R$ 5.500 de ago a dez. | D7: No acumulado jan–jul o efeito líquido é de apenas R$ 500 acima do orçado (−R$ 1.500 em jan–mar, +R$ 2.000 em abr–jul), e mais R$ 2.500 previstos até dezembro. Ao contrário do aumento do Vinicius, este estourou o orçado: não havia folga na linha dela. | E7: Cristiane | F7: APLICADO
A8: D | B8: Jusbrasil 30% acima do orçado | C8: Orçado R$ 104,90/mês, realizado R$ 136,00/mês em mai, jun e jul. | D8: Menor desvio em reais (R$ 31,10/mês), mas o maior em percentual. Vale conferir se houve reajuste contratual ou mudança de plano. | E8: Cristiane | F8: EM ABERTO
A9: E | B9: Bonificação de ago/26 do Jurídico | C9: Estão orçados R$ 10.293,60 em agosto e R$ 12.867,00 em dezembro. O realizado de agosto ainda não foi informado. | D9: É a maior despesa isolada do Jurídico no segundo semestre. | E9: Cristiane | F9: EM ABERTO
A10: F | B10: Jonathan R$ 3.700/mês abaixo do contratado | C10: Orçado R$ 10.000/mês, realizado R$ 6.300/mês em mai, jun e jul. | D10: Maior desvio em reais de todo o orçamento: R$ 11.100 em três meses. Se o valor menor for o novo padrão, o planejado de ago a dez deve ser revisado para baixo — sobrariam R$ 18.500 no orçamento do TI. | E10: Cristiane | F10: EM ABERTO
A11: G | B11: Elias Benedito zerado nos três meses | C11: Orçado R$ 1.065/mês como suporte técnico terceirizado, realizado R$ 0 em mai, jun e jul. | D11: Confirmar se o contrato segue ativo (acionamento sob demanda) ou se foi encerrado. Se encerrado, são R$ 12.780 a liberar no orçamento do ano. | E11: Cristiane | F11: EM ABERTO
A12: H | B12: Planejado de jan a abr — CONFERIR | C12: O 1º quadrimestre foi preenchido replicando os valores mensais conhecidos, porque a ficha original só trazia o grid de mai a dez. Exceções tratadas: Jonathan começa em abr, Thamar a R$ 5.000 (pré-reajuste), Vinicius com bruto de R$ 2.570,52 e Adapta a R$ 1.300 (valor até jun). | D12: Se algum contrato tinha valor diferente no 1º quadrimestre, ou se houve bonificação nesse período, o planejado de jan a abr precisa ser corrigido antes de comparar com o realizado. | E12: Cristiane | F12: CONFERIR
A13: I | B13: Realizado de ago a dez — a lançar no decorrer do ano | C13: Jan a jul estão lançados. Ago a dez ficam em branco e serão preenchidos conforme os meses fecharem, com a extração do SIENGE. | D13: Enquanto isso, o mês de referência do Comparativo deve ficar no último mês fechado (hoje Jul/26) — assim o acumulado compara períodos iguais dos dois lados. | E13: Cristiane | F13: EM ANDAMENTO
A14: M | B14: Despesas fora do orçamento identificadas no extrato | C14: O extrato do financeiro traz gastos relevantes sem linha na ficha. Jurídico: Carneiro Rabelo (R$ 107.742) e Cristiane Carneiro Rabelo (R$ 94.825), somando R$ 202.567 em sete meses; mais Tribunal de Justiça (R$ 49.244), Michele de Oliveira (R$ 23.572) e ONR (R$ 22.576). TI: J H Alves / Monitor Remoto (R$ 20.509) e um bloco de telefonia e infraestrutura de cerca de R$ 15.700 (Claro, TIM, Telefônica, Locaweb, Web Mobile, Sabha, Intelbras, VC1, Alfama). | D14: Só os dois primeiros credores do Jurídico superam o orçamento anual inteiro do departamento. Decidir na reunião quais entram no centro de custo da área — e, para os que entrarem, criar linha no orçamento, senão aparecerão como 'Não orçado' e distorcerão o comparativo. | E14: Cristiane + Diretoria | F14: PAUTA REUNIÃO
A15: J | B15: Despesas do TI — A LANÇAR | C15: As 9 linhas de despesas do TI (peças, backup, Adapta, antivírus, Office, sala de reunião, cursos, app de gravação e bonificação) não têm lançamento em nenhum mês. | D15: São R$ 89.040 orçados no ano, 35% do orçamento do TI. Sem lançamento, o departamento aparece com desvio negativo que é ausência de dado. | E15: Cristiane | F15: A LANÇAR
... A24: 7 | B24: Competência x caixa — DEFASAGEM CONFIRMADA | C24: O pagamento do Miguel de 01/08/26 refere-se a julho, então há pelo menos um prestador cujo pagamento cai no mês seguinte ao da prestação. Todo o realizado está lançado por CAIXA (mês em que o pagamento saiu), que é como os valores foram informados. | D24: Consequência: o valor lançado em jan/26 pode ser referente a dez/2025, e o serviço de dez/26 só aparecerá em jan/2027 — o ano fecha com 12 pagamentos, mas defasados em relação ao orçamento, que é de competência. Com a extração vindo do SIENGE, basta escolher o regime na hora de gerar o relatório: definir isso UMA vez e manter, para o histórico não misturar critérios. | E24: Cristiane + Financeiro | F24: DECIDIR

Sheet Como usar
A1: COMO USAR ESTA PLANILHA
A2: Rotina mensal de fechamento em 5 passos.
A4: ROTINA MENSAL
A5: 1 | B5: Extraia do SIENGE o relatório do centro de custo do departamento, no mês que fechou. A fonte do realizado é o SIENGE — nada é digitado de cabeça.
A6: 2 | B6: Lance na aba REALIZADO, nas células amarelas, o valor de cada linha do orçamento. Item sem gasto no mês: digite 0 — deixar em branco significa 'ainda não lancei'. Use a coluna 'Fonte do dado' para registrar de qual relatório o número saiu, com a data da extração.
A7: 3 | B7: Vá na aba COMPARATIVO e selecione o mês em B3. Todas as demais abas acompanham essa escolha.
A8: 4 | B8: Confira o PAINEL: ele mostra o desvio por departamento e os 5 maiores estouros do acumulado. É a tela para levar à diretoria.
A9: 5 | B9: Atualize a aba PENDÊNCIAS conforme as decisões forem sendo tomadas.
A11: COMO LER OS NÚMEROS
A12: Desvio positivo (vermelho) | B12: Gastou ACIMA do orçado.
A13: Desvio negativo (verde) | B13: Gastou ABAIXO do orçado — economia ou despesa ainda não realizada.
A14: Planejado acum. | B14: Soma de maio até o mês selecionado.
A15: % Executado | B15: Realizado acumulado ÷ Planejado acumulado. Perto de 100% = no ritmo.
A16: Sem lançamento | B16: Nada foi lançado no realizado ainda — não confunda com economia.
A18: REGRAS DA PLANILHA
A19: Não altere | B19: As colunas de identificação da aba Realizado (A a G) são fórmulas que espelham a aba Planejado. Alterar quebra o comparativo.
A20: Nova linha de orçamento | B20: Insira na aba Planejado e replique a mesma linha na aba Realizado e na aba Comparativo, mantendo o mesmo ID.
A21: Revisão de orçamento | B21: Se a diretoria aprovar um valor novo, altere na aba Planejado e registre o motivo na aba Pendências.

Sheet Contas Pagas (resumo)
A1: CONTAS PAGAS — RESUMO POR CREDOR (Jurídico e TI)
A2: Extrato do financeiro, centro de custo "Jurídico + T.I". ABA DE APOIO: o centro de custo destes itens ainda não foi decidido, então nada aqui entra no Planejado, no Realizado nem no Painel. A coluna final aponta o que provavelmente já está no orçamento — confira e remova as duplicidades à mão.
A4: Credor | B4: Centro de Custo | C4: Nº lanç. | D4: Jan/26 | E4: Fev/26 | F4: Mar/26 | G4: Abr/26 | H4: Mai/26 | I4: Jun/26 | J4: Jul/26 | K4: TOTAL | L4: Já está no orçamento?
A5: CARNEIRO RABELO SOCIEDADE INDIVIDUAL DE ADVOCACIA | B5: Júridico | C5: 7 | E5: 23257.53 | F5: 13954.52 | G5: 17632.15 | H5: 17632.15 | I5: 17632.15 | J5: 17633.95 | K5: 107742.45
A6: Cristiane Carneiro Rabelo | B6: Júridico | C6: 14 | D6: 33708.48 | E6: 16231.62 | G6: 2774.32 | I6: 1099.9 | J6: 41010.45 | K6: 94824.77
